Workbook
Name Dataload: TickerList!$B$2:$E$75
Name SelRow: 5
Name SelRowNum: 5
Name StripName: TickerList!$H$2:$H$96
Name StripTick: TickerList!$F$2:$F$75
Name T_List: TickerList!$A$2:$A$75

Sheet DataRT
A1: =MAX(E3:E96) | B1: Today | E1: Today | F1: =NOW() | P1: 58505147 | X1: From DataLocal Sheet2
A2: Ticker_Symbol | B2: ExchR | C2: Company Name | D2: Currency | E2: Last_trade_time | F2: Close | G2: Open | H2: M_Price | I2: Low | J2: High | K2: P/E | L2: Change | M2: Change% | N2: 52_week_low | O2: 52_week_high | P2: Volume | Q2: Volume average | R2: Beta | S2: suffix | T2: Custody2 | U2: Exchange abbreviation | V2: V/VA | W2: Column1 | X2: 1YT | Y2: Ddate | Z2: EarningDate | AA2: RepDiv | AB2: Broker | AC2: Stamp | AD2: Old1YT | AE2: YTChange | AF2: Column2
A3: {=_xlfn.SINGLE(DataRT!$S$3:$S$96)&_FV(DataRT!$C3,"Ticker symbol",TRUE)} | B3: =D99 | C3: #VALUE! | D3: {=_FV(DataRT!$C3,"Currency")} | E3: {=_FV(DataRT!$C3,"Last trade time",TRUE)} | F3: {=_FV(DataRT!$C3,"Previous close",TRUE)} | G3: {=IFERROR(_FV(DataRT!$C3,"Open"),DataRT!$F3)} | H3: {=_FV(DataRT!$C3,"Price")} | I3: {=IFERROR(_FV(DataRT!$C3,"Low"),0)} | J3: {=IFERROR(_FV(DataRT!$C3,"High"),0)} | K3: {=IFERROR(_FV(DataRT!$C3,"P/E",TRUE),99)} | L3: {=_FV(DataRT!$C3,"Change")} | M3: {=_FV(DataRT!$C3,"Change (%)",TRUE)} | N3: {=_FV(DataRT!$C3,"52 week low",TRUE)} | O3: {=_FV(DataRT!$C3,"52 week high",TRUE)} | P3: {=_FV(DataRT!$C3,"Volume")} | Q3: {=_FV(DataRT!$C3,"Volume average",TRUE)} | R3: {=_FV(DataRT!$C3,"Beta")} | T3: V | U3: {=_FV(DataRT!$C3,"Exchange abbreviation",TRUE)} | V3: =IFERROR(DataRT!$P3/DataRT!$Q3,1) | X3: =_xlfn.XLOOKUP(DataRT!$A3,TickerList!$G2:$G96,TickerList!L2:L96) | Y3: =_xlfn.XLOOKUP(DataRT!$A3,TickerList!$G2:$G96,TickerList!M2:M96) | Z3: =_xlfn.XLOOKUP(DataRT!$A3,TickerList!$G2:$G96,TickerList!N2:N96) | AA3: =_xlfn.XLOOKUP(DataRT!$A3,TickerList!$G2:$G96,TickerList!O2:O96) | AB3: 0.0001 | AC3: 0.003 | AD3: 245.31 | AE3: =_xlfn.LET(_xlpm.New1YT,DataRT!$X3, _xlpm.Old1YT,IF(ISNUMBER(DataRT!$AD3),DataRT!$AD3,VALUE(LEFT(DataRT!$AD3,FIND("/",DataRT!$AD3,1)-1))), IF(OR(DataRT!$X3=0,_xlpm.Old1YT=0),0,(_xlpm.New1YT-_xlpm.Old1YT)/_xlpm.Old1YT)) | AF3: =TEXT(DataRT!$X3,"#,#0.00")&" < "&DataRT!$AD3
A4: {=_xlfn.SINGLE(DataRT!$S$3:$S$96)&_FV(DataRT!$C4,"Ticker symbol",TRUE)} | B4: =D99 | C4: #VALUE! | D4: {=_FV(DataRT!$C4,"Currency")} | E4: {=_FV(DataRT!$C4,"Last trade time",TRUE)} | F4: {=_FV(DataRT!$C4,"Previous close",TRUE)} | G4: {=IFERROR(_FV(DataRT!$C4,"Open"),DataRT!$F4)} | H4: {=_FV(DataRT!$C4,"Price")} | I4: {=IFERROR(_FV(DataRT!$C4,"Low"),0)} | J4: {=IFERROR(_FV(DataRT!$C4,"High"),0)} | K4: {=IFERROR(_FV(DataRT!$C4,"P/E",TRUE),99)} | L4: {=_FV(DataRT!$C4,"Change")} | M4: {=_FV(DataRT!$C4,"Change (%)",TRUE)} | N4: {=_FV(DataRT!$C4,"52 week low",TRUE)} | O4: {=_FV(DataRT!$C4,"52 week high",TRUE)} | P4: {=_FV(DataRT!$C4,"Volume")} | Q4: {=_FV(DataRT!$C4,"Volume average",TRUE)} | R4: {=_FV(DataRT!$C4,"Beta")} | T4: V | U4: {=_FV(DataRT!$C4,"Exchange abbreviation",TRUE)} | V4: =IFERROR(DataRT!$P4/DataRT!$Q4,1) | X4: =_xlfn.XLOOKUP(DataRT!$A4,TickerList!$G3:$G97,TickerList!L3:L97) | Y4: =_xlfn.XLOOKUP(DataRT!$A4,TickerList!$G3:$G97,TickerList!M3:M97) | Z4: =_xlfn.XLOOKUP(DataRT!$A4,TickerList!$G3:$G97,TickerList!N3:N97) | AA4: =_xlfn.XLOOKUP(DataRT!$A4,TickerList!$G3:$G97,TickerList!O3:O97) | AB4: 0.0001 | AC4: 0.003 | AD4: 15.33 | AE4: =_xlfn.LET(_xlpm.New1YT,DataRT!$X4, _xlpm.Old1YT,IF(ISNUMBER(DataRT!$AD4),DataRT!$AD4,VALUE(LEFT(DataRT!$AD4,FIND("/",DataRT!$AD4,1)-1))), IF(OR(DataRT!$X4=0,_xlpm.Old1YT=0),0,(_xlpm.New1YT-_xlpm.Old1YT)/_xlpm.Old1YT)) | AF4: =TEXT(DataRT!$X4,"#,#0.00")&" < "&DataRT!$AD4
A5: {=_xlfn.SINGLE(DataRT!$S$3:$S$96)&_FV(DataRT!$C5,"Ticker symbol",TRUE)} | B5: =D101/100 | C5: #VALUE! | D5: {=_FV(DataRT!$C5,"Currency")} | E5: {=_FV(DataRT!$C5,"Last trade time",TRUE)} | F5: {=_FV(DataRT!$C5,"Previous close",TRUE)} | G5: {=IFERROR(_FV(DataRT!$C5,"Open"),DataRT!$F5)} | H5: {=_FV(DataRT!$C5,"Price")} | I5: {=IFERROR(_FV(DataRT!$C5,"Low"),0)} | J5: {=IFERROR(_FV(DataRT!$C5,"High"),0)} | K5: {=IFERROR(_FV(DataRT!$C5,"P/E",TRUE),99)} | L5: {=_FV(DataRT!$C5,"Change")} | M5: {=_FV(DataRT!$C5,"Change (%)",TRUE)} | N5: {=_FV(DataRT!$C5,"52 week low",TRUE)} | O5: {=_FV(DataRT!$C5,"52 week high",TRUE)} | P5: {=_FV(DataRT!$C5,"Volume")} | Q5: {=_FV(DataRT!$C5,"Volume average",TRUE)} | R5: {=_FV(DataRT!$C5,"Beta")} | T5: V | U5: {=_FV(DataRT!$C5,"Exchange abbreviation",TRUE)} | V5: =IFERROR(DataRT!$P5/DataRT!$Q5,1) | X5: =_xlfn.XLOOKUP(DataRT!$A5,TickerList!$G4:$G98,TickerList!L4:L98) | Y5: =_xlfn.XLOOKUP(DataRT!$A5,TickerList!$G4:$G98,TickerList!M4:M98) | Z5: =_xlfn.XLOOKUP(DataRT!$A5,TickerList!$G4:$G98,TickerList!N4:N98) | AA5: =_xlfn.XLOOKUP(DataRT!$A5,TickerList!$G4:$G98,TickerList!O4:O98) | AC5: 0.003 | AD5: 91.96/86.78 | AE5: =_xlfn.LET(_xlpm.New1YT,DataRT!$X5, _xlpm.Old1YT,IF(ISNUMBER(DataRT!$AD5),DataRT!$AD5,VALUE(LEFT(DataRT!$AD5,FIND("/",DataRT!$AD5,1)-1))), IF(OR(DataRT!$X5=0,_xlpm.Old1YT=0),0,(_xlpm.New1YT-_xlpm.Old1YT)/_xlpm.Old1YT)) | AF5: =TEXT(DataRT!$X5,"#,#0.00")&" < "&DataRT!$AD5
A6: {=_xlfn.SINGLE(DataRT!$S$3:$S$96)&_FV(DataRT!$C6,"Ticker symbol",TRUE)} | B6: =D99 | C6: #VALUE! | D6: {=_FV(DataRT!$C6,"Currency")} | E6: {=_FV(DataRT!$C6,"Last trade time",TRUE)} | F6: {=_FV(DataRT!$C6,"Previous close",TRUE)} | G6: {=IFERROR(_FV(DataRT!$C6,"Open"),DataRT!$F6)} | H6: {=_FV(DataRT!$C6,"Price")} | I6: {=IFERROR(_FV(DataRT!$C6,"Low"),0)} | J6: {=IFERROR(_FV(DataRT!$C6,"High"),0)} | K6: {=IFERROR(_FV(DataRT!$C6,"P/E",TRUE),99)} | L6: {=_FV(DataRT!$C6,"Change")} | M6: {=_FV(DataRT!$C6,"Change (%)",TRUE)} | N6: {=_FV(DataRT!$C6,"52 week low",TRUE)} | O6: {=_FV(DataRT!$C6,"52 week high",TRUE)} | P6: {=_FV(DataRT!$C6,"Volume")} | Q6: {=_FV(DataRT!$C6,"Volume average",TRUE)} | R6: {=_FV(DataRT!$C6,"Beta")} | T6: V | U6: {=_FV(DataRT!$C6,"Exchange abbreviation",TRUE)} | V6: =IFERROR(DataRT!$P6/DataRT!$Q6,1) | X6: =_xlfn.XLOOKUP(DataRT!$A6,TickerList!$G5:$G99,TickerList!L5:L99) | Y6: =_xlfn.XLOOKUP(DataRT!$A6,TickerList!$G5:$G99,TickerList!M5:M99) | Z6: =_xlfn.XLOOKUP(DataRT!$A6,TickerList!$G5:$G99,TickerList!N5:N99) | AA6: =_xlfn.XLOOKUP(DataRT!$A6,TickerList!$G5:$G99,TickerList!O5:O99) | AB6: 0.0001 | AC6: 0.003 | AD6: 238.96/218.19 | AE6: =_xlfn.LET(_xlpm.New1YT,DataRT!$X6, _xlpm.Old1YT,IF(ISNUMBER(DataRT!$AD6),DataRT!$AD6,VALUE(LEFT(DataRT!$AD6,FIND("/",DataRT!$AD6,1)-1))), IF(OR(DataRT!$X6=0,_xlpm.Old1YT=0),0,(_xlpm.New1YT-_xlpm.Old1YT)/_xlpm.Old1YT)) | AF6: =TEXT(DataRT!$X6,"#,#0.00")&" < "&DataRT!$AD6
A7: {=_xlfn.SINGLE(DataRT!$S$3:$S$96)&_FV(DataRT!$C7,"Ticker symbol",TRUE)} | B7: 1 | C7: #VALUE! | D7: {=_FV(DataRT!$C7,"Currency")} | E7: {=_FV(DataRT!$C7,"Last trade time",TRUE)} | F7: {=_FV(DataRT!$C7,"Previous close",TRUE)} | G7: {=IFERROR(_FV(DataRT!$C7,"Open"),DataRT!$F7)} | H7: {=_FV(DataRT!$C7,"Price")} | I7: {=IFERROR(_FV(DataRT!$C7,"Low"),0)} | J7: {=IFERROR(_FV(DataRT!$C7,"High"),0)} | K7: {=IFERROR(_FV(DataRT!$C7,"P/E",TRUE),99)} | L7: {=_FV(DataRT!$C7,"Change")} | M7: {=_FV(DataRT!$C7,"Change (%)",TRUE)} | N7: {=_FV(DataRT!$C7,"52 week low",TRUE)} | O7: {=_FV(DataRT!$C7,"52 week high",TRUE)} | P7: {=_FV(DataRT!$C7,"Volume")} | Q7: {=_FV(DataRT!$C7,"Volume average",TRUE)} | R7: {=_FV(DataRT!$C7,"Beta")} | T7: V | U7: {=_FV(DataRT!$C7,"Exchange abbreviation",TRUE)} | V7: =IFERROR(DataRT!$P7/DataRT!$Q7,1) | X7: =_xlfn.XLOOKUP(DataRT!$A7,TickerList!$G6:$G100,TickerList!L6:L100) | Y7: =_xlfn.XLOOKUP(DataRT!$A7,TickerList!$G6:$G100,TickerList!M6:M100) | Z7: =_xlfn.XLOOKUP(DataRT!$A7,TickerList!$G6:$G100,TickerList!N6:N100) | AA7: =_xlfn.XLOOKUP(DataRT!$A7,TickerList!$G6:$G100,TickerList!O6:O100) | AC7: 0.003 | AD7: 3.87 | AE7: =_xlfn.LET(_xlpm.New1YT,DataRT!$X7, _xlpm.Old1YT,IF(ISNUMBER(DataRT!$AD7),DataRT!$AD7,VALUE(LEFT(DataRT!$AD7,FIND("/",DataRT!$AD7,1)-1))), IF(OR(DataRT!$X7=0,_xlpm.Old1YT=0),0,(_xlpm.New1YT-_xlpm.Old1YT)/_xlpm.Old1YT)) | AF7: =TEXT(DataRT!$X7,"#,#0.00")&" < "&DataRT!$AD7
A8: {=_xlfn.SINGLE(DataRT!$S$3:$S$96)&_FV(DataRT!$C8,"Ticker symbol",TRUE)} | B8: 1 | C8: #VALUE! | D8: {=_FV(DataRT!$C8,"Currency")} | E8: {=_FV(DataRT!$C8,"Last trade time",TRUE)} | F8: {=_FV(DataRT!$C8,"Previous close",TRUE)} | G8: {=IFERROR(_FV(DataRT!$C8,"Open"),DataRT!$F8)} | H8: {=_FV(DataRT!$C8,"Price")} | I8: {=IFERROR(_FV(DataRT!$C8,"Low"),0)} | J8: {=IFERROR(_FV(DataRT!$C8,"High"),0)} | K8: {=IFERROR(_FV(DataRT!$C8,"P/E",TRUE),99)} | L8: {=_FV(DataRT!$C8,"Change")} | M8: {=_FV(DataRT!$C8,"Change (%)",TRUE)} | N8: {=_FV(DataRT!$C8,"52 week low",TRUE)} | O8: {=_FV(DataRT!$C8,"52 week high",TRUE)} | P8: {=_FV(DataRT!$C8,"Volume")} | Q8: {=_FV(DataRT!$C8,"Volume average",TRUE)} | R8: {=_FV(DataRT!$C8,"Beta")} | T8: V | U8: {=_FV(DataRT!$C8,"Exchange abbreviation",TRUE)} | V8: =IFERROR(DataRT!$P8/DataRT!$Q8,1) | X8: =_xlfn.XLOOKUP(DataRT!$A8,TickerList!$G7:$G101,TickerList!L7:L101) | Y8: =_xlfn.XLOOKUP(DataRT!$A8,TickerList!$G7:$G101,TickerList!M7:M101) | Z8: =_xlfn.XLOOKUP(DataRT!$A8,TickerList!$G7:$G101,TickerList!N7:N101) | AA8: =_xlfn.XLOOKUP(DataRT!$A8,TickerList!$G7:$G101,TickerList!O7:O101) | AC8: 0.003 | AD8: 847.58 | AE8: =_xlfn.LET(_xlpm.New1YT,DataRT!$X8, _xlpm.Old1YT,IF(ISNUMBER(DataRT!$AD8),DataRT!$AD8,VALUE(LEFT(DataRT!$AD8,FIND("/",DataRT!$AD8,1)-1))), IF(OR(DataRT!$X8=0,_xlpm.Old1YT=0),0,(_xlpm.New1YT-_xlpm.Old1YT)/_xlpm.Old1YT)) | AF8: =TEXT(DataRT!$X8,"#,#0.00")&" < "&DataRT!$AD8
A9: {=_xlfn.SINGLE(DataRT!$S$3:$S$96)&_FV(DataRT!$C9,"Ticker symbol",TRUE)} | B9: 1 | C9: #VALUE! | D9: {=_FV(DataRT!$C9,"Currency")} | E9: {=_FV(DataRT!$C9,"Last trade time",TRUE)} | F9: {=_FV(DataRT!$C9,"Previous close",TRUE)} | G9: {=IFERROR(_FV(DataRT!$C9,"Open"),DataRT!$F9)} | H9: {=_FV(DataRT!$C9,"Price")} | I9: {=IFERROR(_FV(DataRT!$C9,"Low"),0)} | J9: {=IFERROR(_FV(DataRT!$C9,"High"),0)} | K9: {=IFERROR(_FV(DataRT!$C9,"P/E",TRUE),99)} | L9: {=_FV(DataRT!$C9,"Change")} | M9: {=_FV(DataRT!$C9,"Change (%)",TRUE)} | N9: {=_FV(DataRT!$C9,"52 week low",TRUE)} | O9: {=_FV(DataRT!$C9,"52 week high",TRUE)} | P9: {=_FV(DataRT!$C9,"Volume")} | Q9: {=_FV(DataRT!$C9,"Volume average",TRUE)} | R9: {=_FV(DataRT!$C9,"Beta")} | U9: {=_FV(DataRT!$C9,"Exchange abbreviation",TRUE)} | V9: =IFERROR(DataRT!$P9/DataRT!$Q9,1) | X9: =_xlfn.XLOOKUP(DataRT!$A9,TickerList!$G8:$G102,TickerList!L8:L102) | Y9: =_xlfn.XLOOKUP(DataRT!$A9,TickerList!$G8:$G102,TickerList!M8:M102) | Z9: =_xlfn.XLOOKUP(DataRT!$A9,TickerList!$G8:$G102,TickerList!N8:N102) | AA9: =_xlfn.XLOOKUP(DataRT!$A9,TickerList!$G8:$G102,TickerList!O8:O102) | AC9: 0.003 | AD9: 848.58 | AE9: =_xlfn.LET(_xlpm.New1YT,DataRT!$X9, _xlpm.Old1YT,IF(ISNUMBER(DataRT!$AD9),DataRT!$AD9,VALUE(LEFT(DataRT!$AD9,FIND("/",DataRT!$AD9,1)-1))), IF(OR(DataRT!$X9=0,_xlpm.Old1YT=0),0,(_xlpm.New1YT-_xlpm.Old1YT)/_xlpm.Old1YT)) | AF9: =TEXT(DataRT!$X9,"#,#0.00")&" < "&DataRT!$AD9
A10: {=_xlfn.SINGLE(DataRT!$S$3:$S$96)&_FV(DataRT!$C10,"Ticker symbol",TRUE)} | B10: 1 | C10: #VALUE! | D10: {=_FV(DataRT!$C10,"Currency")} | E10: {=_FV(DataRT!$C10,"Last trade time",TRUE)} | F10: {=_FV(DataRT!$C10,"Previous close",TRUE)} | G10: {=IFERROR(_FV(DataRT!$C10,"Open"),DataRT!$F10)} | H10: {=_FV(DataRT!$C10,"Price")} | I10: {=IFERROR(_FV(DataRT!$C10,"Low"),0)} | J10: {=IFERROR(_FV(DataRT!$C10,"High"),0)} | K10: {=IFERROR(_FV(DataRT!$C10,"P/E",TRUE),99)} | L10: {=_FV(DataRT!$C10,"Change")} | M10: {=_FV(DataRT!$C10,"Change (%)",TRUE)} | N10: {=_FV(DataRT!$C10,"52 week low",TRUE)} | O10: {=_FV(DataRT!$C10,"52 week high",TRUE)} | P10: {=_FV(DataRT!$C10,"Volume")} | Q10: {=_FV(DataRT!$C10,"Volume average",TRUE)} | R10: {=_FV(DataRT!$C10,"Beta")} | U10: {=_FV(DataRT!$C10,"Exchange abbreviation",TRUE)} | V10: =IFERROR(DataRT!$P10/DataRT!$Q10,1) | X10: =_xlfn.XLOOKUP(DataRT!$A10,TickerList!$G9:$G103,TickerList!L9:L103) | Y10: =_xlfn.XLOOKUP(DataRT!$A10,TickerList!$G9:$G103,TickerList!M9:M103) | Z10: =_xlfn.XLOOKUP(DataRT!$A10,TickerList!$G9:$G103,TickerList!N9:N103) | AA10: =_xlfn.XLOOKUP(DataRT!$A10,TickerList!$G9:$G103,TickerList!O9:O103) | AC10: 0.003 | AD10: 849.58 | AE10: =_xlfn.LET(_xlpm.New1YT,DataRT!$X10, _xlpm.Old1YT,IF(ISNUMBER(DataRT!$AD10),DataRT!$AD10,VALUE(LEFT(DataRT!$AD10,FIND("/",DataRT!$AD10,1)-1))), IF(OR(DataRT!$X10=0,_xlpm.Old1YT=0),0,(_xlpm.New1YT-_xlpm.Old1YT)/_xlpm.Old1YT)) | AF10: =TEXT(DataRT!$X10,"#,#0.00")&" < "&DataRT!$AD10
A11: {=_xlfn.SINGLE(DataRT!$S$3:$S$96)&_FV(DataRT!$C11,"Ticker symbol",TRUE)} | B11: =D99 | C11: #VALUE! | D11: {=_FV(DataRT!$C11,"Currency")} | E11: {=_FV(DataRT!$C11,"Last trade time",TRUE)} | F11: {=_FV(DataRT!$C11,"Previous close",TRUE)} | G11: {=IFERROR(_FV(DataRT!$C11,"Open"),DataRT!$F11)} | H11: {=_FV(DataRT!$C11,"Price")} | I11: {=IFERROR(_FV(DataRT!$C11,"Low"),0)} | J11: {=IFERROR(_FV(DataRT!$C11,"High"),0)} | K11: {=IFERROR(_FV(DataRT!$C11,"P/E",TRUE),99)} | L11: {=_FV(DataRT!$C11,"Change")} | M11: {=_FV(DataRT!$C11,"Change (%)",TRUE)} | N11: {=_FV(DataRT!$C11,"52 week low",TRUE)} | O11: {=_FV(DataRT!$C11,"52 week high",TRUE)} | P11: {=_FV(DataRT!$C11,"Volume")} | Q11: {=_FV(DataRT!$C11,"Volume average",TRUE)} | R11: {=_FV(DataRT!$C11,"Beta")} | T11: V | U11: {=_FV(DataRT!$C11,"Exchange abbreviation",TRUE)} | V11: =IFERROR(DataRT!$P11/DataRT!$Q11,1) | X11: =_xlfn.XLOOKUP(DataRT!$A11,TickerList!$G10:$G104,TickerList!L10:L104) | Y11: =_xlfn.XLOOKUP(DataRT!$A11,TickerList!$G10:$G104,TickerList!M10:M104) | Z11: =_xlfn.XLOOKUP(DataRT!$A11,TickerList!$G10:$G104,TickerList!N10:N104) | AA11: =_xlfn.XLOOKUP(DataRT!$A11,TickerList!$G10:$G104,TickerList!O10:O104) | AB11: 0.0001 | AC11: 0.003 | AD11: 90.46 | AE11: =_xlfn.LET(_xlpm.New1YT,DataRT!$X11, _xlpm.Old1YT,IF(ISNUMBER(DataRT!$AD11),DataRT!$AD11,VALUE(LEFT(DataRT!$AD11,FIND("/",DataRT!$AD11,1)-1))), IF(OR(DataRT!$X11=0,_xlpm.Old1YT=0),0,(_xlpm.New1YT-_xlpm.Old1YT)/_xlpm.Old1YT)) | AF11: =TEXT(DataRT!$X11,"#,#0.00")&" < "&DataRT!$AD11
A12: {=_xlfn.SINGLE(DataRT!$S$3:$S$96)&_FV(DataRT!$C12,"Ticker symbol",TRUE)} | B12: =D99 | C12: #VALUE! | D12: {=_FV(DataRT!$C12,"Currency")} | E12: {=_FV(DataRT!$C12,"Last trade time",TRUE)} | F12: {=_FV(DataRT!$C12,"Previous close",TRUE)} | G12: {=IFERROR(_FV(DataRT!$C12,"Open"),DataRT!$F12)} | H12: {=_FV(DataRT!$C12,"Price")} | I12: {=IFERROR(_FV(DataRT!$C12,"Low"),0)} | J12: {=IFERROR(_FV(DataRT!$C12,"High"),0)} | K12: {=IFERROR(_FV(DataRT!$C12,"P/E",TRUE),99)} | L12: {=_FV(DataRT!$C12,"Change")} | M12: {=_FV(DataRT!$C12,"Change (%)",TRUE)} | N12: {=_FV(DataRT!$C12,"52 week low",TRUE)} | O12: {=_FV(DataRT!$C12,"52 week high",TRUE)} | P12: {=_FV(DataRT!$C12,"Volume")} | Q12: {=_FV(DataRT!$C12,"Volume average",TRUE)} | R12: {=_FV(DataRT!$C12,"Beta")} | T12: V | U12: {=_FV(DataRT!$C12,"Exchange abbreviation",TRUE)} | V12: =IFERROR(DataRT!$P12/DataRT!$Q12,1) | X12: =_xlfn.XLOOKUP(DataRT!$A12,TickerList!$G11:$G105,TickerList!L11:L105) | Y12: =_xlfn.XLOOKUP(DataRT!$A12,TickerList!$G11:$G105,TickerList!M11:M105) | Z12: =_xlfn.XLOOKUP(DataRT!$A12,TickerList!$G11:$G105,TickerList!N11:N105) | AA12: =_xlfn.XLOOKUP(DataRT!$A12,TickerList!$G11:$G105,TickerList!O11:O105) | AB12: 0.0001 | AC12: 0.003 | AD12: 2.73 | AE12: =_xlfn.LET(_xlpm.New1YT,DataRT!$X12, _xlpm.Old1YT,IF(ISNUMBER(DataRT!$AD12),DataRT!$AD12,VALUE(LEFT(DataRT!$AD12,FIND("/",DataRT!$AD12,1)-1))), IF(OR(DataRT!$X12=0,_xlpm.Old1YT=0),0,(_xlpm.New1YT-_xlpm.Old1YT)/_xlpm.Old1YT)) | AF12: =TEXT(DataRT!$X12,"#,#0.00")&" < "&DataRT!$AD12
A13: {=_xlfn.SINGLE(DataRT!$S$3:$S$96)&_FV(DataRT!$C13,"Ticker symbol",TRUE)} | B13: =D99 | C13: #VALUE! | D13: {=_FV(DataRT!$C13,"Currency")} | E13: {=_FV(DataRT!$C13,"Last trade time",TRUE)} | F13: {=_FV(DataRT!$C13,"Previous close",TRUE)} | G13: {=IFERROR(_FV(DataRT!$C13,"Open"),DataRT!$F13)} | H13: {=_FV(DataRT!$C13,"Price")} | I13: {=IFERROR(_FV(DataRT!$C13,"Low"),0)} | J13: {=IFERROR(_FV(DataRT!$C13,"High"),0)} | K13: {=IFERROR(_FV(DataRT!$C13,"P/E",TRUE),99)} | L13: {=_FV(DataRT!$C13,"Change")} | M13: {=_FV(DataRT!$C13,"Change (%)",TRUE)} | N13: {=_FV(DataRT!$C13,"52 week low",TRUE)} | O13: {=_FV(DataRT!$C13,"52 week high",TRUE)} | P13: {=_FV(DataRT!$C13,"Volume")} | Q13: {=_FV(DataRT!$C13,"Volume average",TRUE)} | R13: {=_FV(DataRT!$C13,"Beta")} | T13: V | U13: {=_FV(DataRT!$C13,"Exchange abbreviation",TRUE)} | V13: =IFERROR(DataRT!$P13/DataRT!$Q13,1) | X13: =_xlfn.XLOOKUP(DataRT!$A13,TickerList!$G12:$G106,TickerList!L12:L106) | Y13: =_xlfn.XLOOKUP(DataRT!$A13,TickerList!$G12:$G106,TickerList!M12:M106) | Z13: =_xlfn.XLOOKUP(DataRT!$A13,TickerList!$G12:$G106,TickerList!N12:N106) | AA13: =_xlfn.XLOOKUP(DataRT!$A13,TickerList!$G12:$G106,TickerList!O12:O106) | AB13: 0.0001 | AC13: 0.003 | AD13: 13.26 | AE13: =_xlfn.LET(_xlpm.New1YT,DataRT!$X13, _xlpm.Old1YT,IF(ISNUMBER(DataRT!$AD13),DataRT!$AD13,VALUE(LEFT(DataRT!$AD13,FIND("/",DataRT!$AD13,1)-1))), IF(OR(DataRT!$X13=0,_xlpm.Old1YT=0),0,(_xlpm.New1YT-_xlpm.Old1YT)/_xlpm.Old1YT)) | AF13: =TEXT(DataRT!$X13,"#,#0.00")&" < "&DataRT!$AD13
A14: {=_xlfn.SINGLE(DataRT!$S$3:$S$96)&_FV(DataRT!$C14,"Ticker symbol",TRUE)} | B14: =D99 | C14: #VALUE! | D14: {=_FV(DataRT!$C14,"Currency")} | E14: {=_FV(DataRT!$C14,"Last trade time",TRUE)} | F14: {=_FV(DataRT!$C14,"Previous close",TRUE)} | G14: {=IFERROR(_FV(DataRT!$C14,"Open"),DataRT!$F14)} | H14: {=_FV(DataRT!$C14,"Price")} | I14: {=IFERROR(_FV(DataRT!$C14,"Low"),0)} | J14: {=IFERROR(_FV(DataRT!$C14,"High"),0)} | K14: {=IFERROR(_FV(DataRT!$C14,"P/E",TRUE),99)} | L14: {=_FV(DataRT!$C14,"Change")} | M14: {=_FV(DataRT!$C14,"Change (%)",TRUE)} | N14: {=_FV(DataRT!$C14,"52 week low",TRUE)} | O14: {=_FV(DataRT!$C14,"52 week high",TRUE)} | P14: {=_FV(DataRT!$C14,"Volume")} | Q14: {=_FV(DataRT!$C14,"Volume average",TRUE)} | R14: {=_FV(DataRT!$C14,"Beta")} | T14: V | U14: {=_FV(DataRT!$C14,"Exchange abbreviation",TRUE)} | V14: =IFERROR(DataRT!$P14/DataRT!$Q14,1) | X14: =_xlfn.XLOOKUP(DataRT!$A14,TickerList!$G13:$G107,TickerList!L13:L107) | Y14: =_xlfn.XLOOKUP(DataRT!$A14,TickerList!$G13:$G107,TickerList!M13:M107) | Z14: =_xlfn.XLOOKUP(DataRT!$A14,TickerList!$G13:$G107,TickerList!N13:N107) | AA14: =_xlfn.XLOOKUP(DataRT!$A14,TickerList!$G13:$G107,TickerList!O13:O107) | AB14: 0.0001 | AC14: 0.003 | AD14: 87.38/72.32 | AE14: =_xlfn.LET(_xlpm.New1YT,DataRT!$X14, _xlpm.Old1YT,IF(ISNUMBER(DataRT!$AD14),DataRT!$AD14,VALUE(LEFT(DataRT!$AD14,FIND("/",DataRT!$AD14,1)-1))), IF(OR(DataRT!$X14=0,_xlpm.Old1YT=0),0,(_xlpm.New1YT-_xlpm.Old1YT)/_xlpm.Old1YT)) | AF14: =TEXT(DataRT!$X14,"#,#0.00")&" < "&DataRT!$AD14
A15: {=_xlfn.SINGLE(DataRT!$S$3:$S$96)&_FV(DataRT!$C15,"Ticker symbol",TRUE)} | B15: =D99 | C15: #VALUE! | D15: {=_FV(DataRT!$C15,"Currency")} | E15: {=_FV(DataRT!$C15,"Last trade time",TRUE)} | F15: {=_FV(DataRT!$C15,"Previous close",TRUE)} | G15: {=IFERROR(_FV(DataRT!$C15,"Open"),DataRT!$F15)} | H15: {=_FV(DataRT!$C15,"Price")} | I15: {=IFERROR(_FV(DataRT!$C15,"Low"),0)} | J15: {=IFERROR(_FV(DataRT!$C15,"High"),0)} | K15: {=IFERROR(_FV(DataRT!$C15,"P/E",TRUE),99)} | L15: {=_FV(DataRT!$C15,"Change")} | M15: {=_FV(DataRT!$C15,"Change (%)",TRUE)} | N15: {=_FV(DataRT!$C15,"52 week low",TRUE)} | O15: {=_FV(DataRT!$C15,"52 week high",TRUE)} | P15: {=_FV(DataRT!$C15,"Volume")} | Q15: {=_FV(DataRT!$C15,"Volume average",TRUE)} | R15: {=_FV(DataRT!$C15,"Beta")} | T15: V | U15: {=_FV(DataRT!$C15,"Exchange abbreviation",TRUE)} | V15: =IFERROR(DataRT!$P15/DataRT!$Q15,1) | X15: =_xlfn.XLOOKUP(DataRT!$A15,TickerList!$G14:$G108,TickerList!L14:L108) | Y15: =_xlfn.XLOOKUP(DataRT!$A15,TickerList!$G14:$G108,TickerList!M14:M108) | Z15: =_xlfn.XLOOKUP(DataRT!$A15,TickerList!$G14:$G108,TickerList!N14:N108) | AA15: =_xlfn.XLOOKUP(DataRT!$A15,TickerList!$G14:$G108,TickerList!O14:O108) | AB15: 0.0001 | AC15: 0.003 | AD15: 75.81476/55.04 | AE15: =_xlfn.LET(_xlpm.New1YT,DataRT!$X15, _xlpm.Old1YT,IF(ISNUMBER(DataRT!$AD15),DataRT!$AD15,VALUE(LEFT(DataRT!$AD15,FIND("/",DataRT!$AD15,1)-1))), IF(OR(DataRT!$X15=0,_xlpm.Old1YT=0),0,(_xlpm.New1YT-_xlpm.Old1YT)/_xlpm.Old1YT)) | AF15: =TEXT(DataRT!$X15,"#,#0.00")&" < "&DataRT!$AD15
A16: {=_xlfn.SINGLE(DataRT!$S$3:$S$96)&_FV(DataRT!$C16,"Ticker symbol",TRUE)} | B16: =D99 | C16: #VALUE! | D16: {=_FV(DataRT!$C16,"Currency")} | E16: {=_FV(DataRT!$C16,"Last trade time",TRUE)} | F16: {=_FV(DataRT!$C16,"Previous close",TRUE)} | G16: {=IFERROR(_FV(DataRT!$C16,"Open"),DataRT!$F16)} | H16: {=_FV(DataRT!$C16,"Price")} | I16: {=IFERROR(_FV(DataRT!$C16,"Low"),0)} | J16: {=IFERROR(_FV(DataRT!$C16,"High"),0)} | K16: {=IFERROR(_FV(DataRT!$C16,"P/E",TRUE),99)} | L16: {=_FV(DataRT!$C16,"Change")} | M16: {=_FV(DataRT!$C16,"Change (%)",TRUE)} | N16: {=_FV(DataRT!$C16,"52 week low",TRUE)} | O16: {=_FV(DataRT!$C16,"52 week high",TRUE)} | P16: {=_FV(DataRT!$C16,"Volume")} | Q16: {=_FV(DataRT!$C16,"Volume average",TRUE)} | R16: {=_FV(DataRT!$C16,"Beta")} | T16: V | U16: {=_FV(DataRT!$C16,"Exchange abbreviation",TRUE)} | V16: =IFERROR(DataRT!$P16/DataRT!$Q16,1) | X16: =_xlfn.XLOOKUP(DataRT!$A16,TickerList!$G15:$G109,TickerList!L15:L109) | Y16: =_xlfn.XLOOKUP(DataRT!$A16,TickerList!$G15:$G109,TickerList!M15:M109) | Z16: =_xlfn.XLOOKUP(DataRT!$A16,TickerList!$G15:$G109,TickerList!N15:N109) | AA16: =_xlfn.XLOOKUP(DataRT!$A16,TickerList!$G15:$G109,TickerList!O15:O109) | AB16: 0.0001 | AC16: 0.003 | AD16: 72.3 | AE16: =_xlfn.LET(_xlpm.New1YT,DataRT!$X16, _xlpm.Old1YT,IF(ISNUMBER(DataRT!$AD16),DataRT!$AD16,VALUE(LEFT(DataRT!$AD16,FIND("/",DataRT!$AD16,1)-1))), IF(OR(DataRT!$X16=0,_xlpm.Old1YT=0),0,(_xlpm.New1YT-_xlpm.Old1YT)/_xlpm.Old1YT)) | AF16: =TEXT(DataRT!$X16,"#,#0.00")&" < "&DataRT!$AD16
A17: {=_xlfn.SINGLE(DataRT!$S$3:$S$96)&_FV(DataRT!$C17,"Ticker symbol",TRUE)} | B17: =D99 | C17: #VALUE! | D17: {=_FV(DataRT!$C17,"Currency")} | E17: {=_FV(DataRT!$C17,"Last trade time",TRUE)} | F17: {=_FV(DataRT!$C17,"Previous close",TRUE)} | G17: {=IFERROR(_FV(DataRT!$C17,"Open"),DataRT!$F17)} | H17: {=_FV(DataRT!$C17,"Price")} | I17: {=IFERROR(_FV(DataRT!$C17,"Low"),0)} | J17: {=IFERROR(_FV(DataRT!$C17,"High"),0)} | K17: {=IFERROR(_FV(DataRT!$C17,"P/E",TRUE),99)} | L17: {=_FV(DataRT!$C17,"Change")} | M17: {=_FV(DataRT!$C17,"Change (%)",TRUE)} | N17: {=_FV(DataRT!$C17,"52 week low",TRUE)} | O17: {=_FV(DataRT!$C17,"52 week high",TRUE)} | P17: {=_FV(DataRT!$C17,"Volume")} | Q17: {=_FV(DataRT!$C17,"Volume average",TRUE)} | R17: {=_FV(DataRT!$C17,"Beta")} | T17: V | U17: {=_FV(DataRT!$C17,"Exchange abbreviation",TRUE)} | V17: =IFERROR(DataRT!$P17/DataRT!$Q17,1) | X17: =_xlfn.XLOOKUP(DataRT!$A17,TickerList!$G16:$G110,TickerList!L16:L110) | Y17: =_xlfn.XLOOKUP(DataRT!$A17,TickerList!$G16:$G110,TickerList!M16:M110) | Z17: =_xlfn.XLOOKUP(DataRT!$A17,TickerList!$G16:$G110,TickerList!N16:N110) | AA17: =_xlfn.XLOOKUP(DataRT!$A17,TickerList!$G16:$G110,TickerList!O16:O110) | AB17: 0.0001 | AC17: 0.003 | AD17: 3.94 | AE17: =_xlfn.LET(_xlpm.New1YT,DataRT!$X17, _xlpm.Old1YT,IF(ISNUMBER(DataRT!$AD17),DataRT!$AD17,VALUE(LEFT(DataRT!$AD17,FIND("/",DataRT!$AD17,1)-1))), IF(OR(DataRT!$X17=0,_xlpm.Old1YT=0),0,(_xlpm.New1YT-_xlpm.Old1YT)/_xlpm.Old1YT)) | AF17: =TEXT(DataRT!$X17,"#,#0.00")&" < "&DataRT!$AD17
A18: {=_xlfn.SINGLE(DataRT!$S$3:$S$96)&_FV(DataRT!$C18,"Ticker symbol",TRUE)} | B18: =D99 | C18: #VALUE! | D18: {=_FV(DataRT!$C18,"Currency")} | E18: {=_FV(DataRT!$C18,"Last trade time",TRUE)} | F18: {=_FV(DataRT!$C18,"Previous close",TRUE)} | G18: {=IFERROR(_FV(DataRT!$C18,"Open"),DataRT!$F18)} | H18: {=_FV(DataRT!$C18,"Price")} | I18: {=IFERROR(_FV(DataRT!$C18,"Low"),0)} | J18: {=IFERROR(_FV(DataRT!$C18,"High"),0)} | K18: {=IFERROR(_FV(DataRT!$C18,"P/E",TRUE),99)} | L18: {=_FV(DataRT!$C18,"Change")} | M18: {=_FV(DataRT!$C18,"Change (%)",TRUE)} | N18: {=_FV(DataRT!$C18,"52 week low",TRUE)} | O18: {=_FV(DataRT!$C18,"52 week high",TRUE)} | P18: {=_FV(DataRT!$C18,"Volume")} | Q18: {=_FV(DataRT!$C18,"Volume average",TRUE)} | R18: {=_FV(DataRT!$C18,"Beta")} | T18: V | U18: {=_FV(DataRT!$C18,"Exchange abbreviation",TRUE)} | V18: =IFERROR(DataRT!$P18/DataRT!$Q18,1) | X18: =_xlfn.XLOOKUP(DataRT!$A18,TickerList!$G17:$G111,TickerList!L17:L111) | Y18: =_xlfn.XLOOKUP(DataRT!$A18,TickerList!$G17:$G111,TickerList!M17:M111) | Z18: =_xlfn.XLOOKUP(DataRT!$A18,TickerList!$G17:$G111,TickerList!N17:N111) | AA18: =_xlfn.XLOOKUP(DataRT!$A18,TickerList!$G17:$G111,TickerList!O17:O111) | AB18: 0.0001 | AC18: 0.003 | AD18: 111.22 | AE18: =_xlfn.LET(_xlpm.New1YT,DataRT!$X18, _xlpm.Old1YT,IF(ISNUMBER(DataRT!$AD18),DataRT!$AD18,VALUE(LEFT(DataRT!$AD18,FIND("/",DataRT!$AD18,1)-1))), IF(OR(DataRT!$X18=0,_xlpm.Old1YT=0),0,(_xlpm.New1YT-_xlpm.Old1YT)/_xlpm.Old1YT)) | AF18: =TEXT(DataRT!$X18,"#,#0.00")&" < "&DataRT!$AD18
A19: {=_xlfn.SINGLE(DataRT!$S$3:$S$96)&_FV(DataRT!$C19,"Ticker symbol",TRUE)} | B19: 1 | C19: #VALUE! | D19: {=_FV(DataRT!$C19,"Currency")} | E19: {=_FV(DataRT!$C19,"Last trade time",TRUE)} | F19: {=_FV(DataRT!$C19,"Previous close",TRUE)} | G19: {=IFERROR(_FV(DataRT!$C19,"Open"),DataRT!$F19)} | H19: {=_FV(DataRT!$C19,"Price")} | I19: {=IFERROR(_FV(DataRT!$C19,"Low"),0)} | J19: {=IFERROR(_FV(DataRT!$C19,"High"),0)} | K19: {=IFERROR(_FV(DataRT!$C19,"P/E",TRUE),99)} | L19: {=_FV(DataRT!$C19,"Change")} | M19: {=_FV(DataRT!$C19,"Change (%)",TRUE)} | N19: {=_FV(DataRT!$C19,"52 week low",TRUE)} | O19: {=_FV(DataRT!$C19,"52 week high",TRUE)} | P19: {=_FV(DataRT!$C19,"Volume")} | Q19: {=_FV(DataRT!$C19,"Volume average",TRUE)} | R19: {=_FV(DataRT!$C19,"Beta")} | T19: V | U19: {=_FV(DataRT!$C19,"Exchange abbreviation",TRUE)} | V19: =IFERROR(DataRT!$P19/DataRT!$Q19,1) | X19: =_xlfn.XLOOKUP(DataRT!$A19,TickerList!$G18:$G112,TickerList!L18:L112) | Y19: =_xlfn.XLOOKUP(DataRT!$A19,TickerList!$G18:$G112,TickerList!M18:M112) | Z19: =_xlfn.XLOOKUP(DataRT!$A19,TickerList!$G18:$G112,TickerList!N18:N112) | AA19: =_xlfn.XLOOKUP(DataRT!$A19,TickerList!$G18:$G112,TickerList!O18:O112) | AC19: 0.003 | AD19: 37.97/38.13/38.23 | AE19: =_xlfn.LET(_xlpm.New1YT,DataRT!$X19, _xlpm.Old1YT,IF(ISNUMBER(DataRT!$AD19),DataRT!$AD19,VALUE(LEFT(DataRT!$AD19,FIND("/",DataRT!$AD19,1)-1))), IF(OR(DataRT!$X19=0,_xlpm.Old1YT=0),0,(_xlpm.New1YT-_xlpm.Old1YT)/_xlpm.Old1YT)) | AF19: =TEXT(DataRT!$X19,"#,#0.00")&" < "&DataRT!$AD19
A20: {=_xlfn.SINGLE(DataRT!$S$3:$S$96)&_FV(DataRT!$C20,"Ticker symbol",TRUE)} | B20: =D99 | C20: #VALUE! | D20: {=_FV(DataRT!$C20,"Currency")} | E20: {=_FV(DataRT!$C20,"Last trade time",TRUE)} | F20: {=_FV(DataRT!$C20,"Previous close",TRUE)} | G20: {=IFERROR(_FV(DataRT!$C20,"Open"),DataRT!$F20)} | H20: {=_FV(DataRT!$C20,"Price")} | I20: {=IFERROR(_FV(DataRT!$C20,"Low"),0)} | J20: {=IFERROR(_FV(DataRT!$C20,"High"),0)} | K20: {=IFERROR(_FV(DataRT!$C20,"P/E",TRUE),99)} | L20: {=_FV(DataRT!$C20,"Change")} | M20: {=_FV(DataRT!$C20,"Change (%)",TRUE)} | N20: {=_FV(DataRT!$C20,"52 week low",TRUE)} | O20: {=_FV(DataRT!$C20,"52 week high",TRUE)} | P20: {=_FV(DataRT!$C20,"Volume")} | Q20: {=_FV(DataRT!$C20,"Volume average",TRUE)} | R20: {=_FV(DataRT!$C20,"Beta")} | T20: V | U20: {=_FV(DataRT!$C20,"Exchange abbreviation",TRUE)} | V20: =IFERROR(DataRT!$P20/DataRT!$Q20,1) | X20: =_xlfn.XLOOKUP(DataRT!$A20,TickerList!$G19:$G113,TickerList!L19:L113) | Y20: =_xlfn.XLOOKUP(DataRT!$A20,TickerList!$G19:$G113,TickerList!M19:M113) | Z20: =_xlfn.XLOOKUP(DataRT!$A20,TickerList!$G19:$G113,TickerList!N19:N113) | AA20: =_xlfn.XLOOKUP(DataRT!$A20,TickerList!$G19:$G113,TickerList!O19:O113) | AB20: 0.0001 | AC20: 0.003 | AD20: 157.9 | AE20: =_xlfn.LET(_xlpm.New1YT,DataRT!$X20, _xlpm.Old1YT,IF(ISNUMBER(DataRT!$AD20),DataRT!$AD20,VALUE(LEFT(DataRT!$AD20,FIND("/",DataRT!$AD20,1)-1))), IF(OR(DataRT!$X20=0,_xlpm.Old1YT=0),0,(_xlpm.New1YT-_xlpm.Old1YT)/_xlpm.Old1YT)) | AF20: =TEXT(DataRT!$X20,"#,#0.00")&" < "&DataRT!$AD20
A21: {=_xlfn.SINGLE(DataRT!$S$3:$S$96)&_FV(DataRT!$C21,"Ticker symbol",TRUE)} | B21: =D99 | C21: #VALUE! | D21: {=_FV(DataRT!$C21,"Currency")} | E21: {=_FV(DataRT!$C21,"Last trade time",TRUE)} | F21: {=_FV(DataRT!$C21,"Previous close",TRUE)} | G21: {=IFERROR(_FV(DataRT!$C21,"Open"),DataRT!$F21)} | H21: {=_FV(DataRT!$C21,"Price")} | I21: {=IFERROR(_FV(DataRT!$C21,"Low"),0)} | J21: {=IFERROR(_FV(DataRT!$C21,"High"),0)} | K21: {=IFERROR(_FV(DataRT!$C21,"P/E",TRUE),99)} | L21: {=_FV(DataRT!$C21,"Change")} | M21: {=_FV(DataRT!$C21,"Change (%)",TRUE)} | N21: {=_FV(DataRT!$C21,"52 week low",TRUE)} | O21: {=_FV(DataRT!$C21,"52 week high",TRUE)} | P21: {=_FV(DataRT!$C21,"Volume")} | Q21: {=_FV(DataRT!$C21,"Volume average",TRUE)} | R21: {=_FV(DataRT!$C21,"Beta")} | T21: V | U21: {=_FV(DataRT!$C21,"Exchange abbreviation",TRUE)} | V21: =IFERROR(DataRT!$P21/DataRT!$Q21,1) | X21: =_xlfn.XLOOKUP(DataRT!$A21,TickerList!$G20:$G114,TickerList!L20:L114) | Y21: =_xlfn.XLOOKUP(DataRT!$A21,TickerList!$G20:$G114,TickerList!M20:M114) | Z21: =_xlfn.XLOOKUP(DataRT!$A21,TickerList!$G20:$G114,TickerList!N20:N114) | AA21: =_xlfn.XLOOKUP(DataRT!$A21,TickerList!$G20:$G114,TickerList!O20:O114) | AB21: 0.0001 | AC21: 0.003 | AD21: 19.77 | AE21: =_xlfn.LET(_xlpm.New1YT,DataRT!$X21, _xlpm.Old1YT,IF(ISNUMBER(DataRT!$AD21),DataRT!$AD21,VALUE(LEFT(DataRT!$AD21,FIND("/",DataRT!$AD21,1)-1))), IF(OR(DataRT!$X21=0,_xlpm.Old1YT=0),0,(_xlpm.New1YT-_xlpm.Old1YT)/_xlpm.Old1YT)) | AF21: =TEXT(DataRT!$X21,"#,#0.00")&" < "&DataRT!$AD21
A22: {=_xlfn.SINGLE(DataRT!$S$3:$S$96)&_FV(DataRT!$C22,"Ticker symbol",TRUE)} | B22: 1 | C22: #VALUE! | D22: {=_FV(DataRT!$C22,"Currency")} | E22: {=_FV(DataRT!$C22,"Last trade time",TRUE)} | F22: {=_FV(DataRT!$C22,"Previous close",TRUE)} | G22: {=IFERROR(_FV(DataRT!$C22,"Open"),DataRT!$F22)} | H22: {=_FV(DataRT!$C22,"Price")} | I22: {=IFERROR(_FV(DataRT!$C22,"Low"),0)} | J22: {=IFERROR(_FV(DataRT!$C22,"High"),0)} | K22: {=IFERROR(_FV(DataRT!$C22,"P/E",TRUE),99)} | L22: {=_FV(DataRT!$C22,"Change")} | M22: {=_FV(DataRT!$C22,"Change (%)",TRUE)} | N22: {=_FV(DataRT!$C22,"52 week low",TRUE)} | O22: {=_FV(DataRT!$C22,"52 week high",TRUE)} | P22: {=_FV(DataRT!$C22,"Volume")} | Q22: {=_FV(DataRT!$C22,"Volume average",TRUE)} | R22: {=_FV(DataRT!$C22,"Beta")} | T22: V | U22: {=_FV(DataRT!$C22,"Exchange abbreviation",TRUE)} | V22: =IFERROR(DataRT!$P22/DataRT!$Q22,1) | X22: =_xlfn.XLOOKUP(DataRT!$A22,TickerList!$G21:$G115,TickerList!L21:L115) | Y22: =_xlfn.XLOOKUP(DataRT!$A22,TickerList!$G21:$G115,TickerList!M21:M115) | Z22: =_xlfn.XLOOKUP(DataRT!$A22,TickerList!$G21:$G115,TickerList!N21:N115) | AA22: =_xlfn.XLOOKUP(DataRT!$A22,TickerList!$G21:$G115,TickerList!O21:O115) | AC22: 0.003 | AD22: 16.71/16.47/14.8 | AE22: =_xlfn.LET(_xlpm.New1YT,DataRT!$X22, _xlpm.Old1YT,IF(ISNUMBER(DataRT!$AD22),DataRT!$AD22,VALUE(LEFT(DataRT!$AD22,FIND("/",DataRT!$AD22,1)-1))), IF(OR(DataRT!$X22=0,_xlpm.Old1YT=0),0,(_xlpm.New1YT-_xlpm.Old1YT)/_xlpm.Old1YT)) | AF22: =TEXT(DataRT!$X22,"#,#0.00")&" < "&DataRT!$AD22
A23: {=_xlfn.SINGLE(DataRT!$S$3:$S$96)&_FV(DataRT!$C23,"Ticker symbol",TRUE)} | B23: =D99 | C23: #VALUE! | D23: {=_FV(DataRT!$C23,"Currency")} | E23: {=_FV(DataRT!$C23,"Last trade time",TRUE)} | F23: {=_FV(DataRT!$C23,"Previous close",TRUE)} | G23: {=IFERROR(_FV(DataRT!$C23,"Open"),DataRT!$F23)} | H23: {=_FV(DataRT!$C23,"Price")} | I23: {=IFERROR(_FV(DataRT!$C23,"Low"),0)} | J23: {=IFERROR(_FV(DataRT!$C23,"High"),0)} | K23: {=IFERROR(_FV(DataRT!$C23,"P/E",TRUE),99)} | L23: {=_FV(DataRT!$C23,"Change")} | M23: {=_FV(DataRT!$C23,"Change (%)",TRUE)} | N23: {=_FV(DataRT!$C23,"52 week low",TRUE)} | O23: {=_FV(DataRT!$C23,"52 week high",TRUE)} | P23: {=_FV(DataRT!$C23,"Volume")} | Q23: {=_FV(DataRT!$C23,"Volume average",TRUE)} | R23: {=_FV(DataRT!$C23,"Beta")} | T23: V | U23: {=_FV(DataRT!$C23,"Exchange abbreviation",TRUE)} | V23: =IFERROR(DataRT!$P23/DataRT!$Q23,1) | X23: =_xlfn.XLOOKUP(DataRT!$A23,TickerList!$G22:$G116,TickerList!L22:L116) | Y23: =_xlfn.XLOOKUP(DataRT!$A23,TickerList!$G22:$G116,TickerList!M22:M116) | Z23: =_xlfn.XLOOKUP(DataRT!$A23,TickerList!$G22:$G116,TickerList!N22:N116) | AA23: =_xlfn.XLOOKUP(DataRT!$A23,TickerList!$G22:$G116,TickerList!O22:O116) | AB23: 0.0001 | AC23: 0.003 | AD23: 9.32 | AE23: =_xlfn.LET(_xlpm.New1YT,DataRT!$X23, _xlpm.Old1YT,IF(ISNUMBER(DataRT!$AD23),DataRT!$AD23,VALUE(LEFT(DataRT!$AD23,FIND("/",DataRT!$AD23,1)-1))), IF(OR(DataRT!$X23=0,_xlpm.Old1YT=0),0,(_xlpm.New1YT-_xlpm.Old1YT)/_xlpm.Old1YT)) | AF23: =TEXT(DataRT!$X23,"#,#0.00")&" < "&DataRT!$AD23
A24: {=_xlfn.SINGLE(DataRT!$S$3:$S$96)&_FV(DataRT!$C24,"Ticker symbol",TRUE)} | B24: =D99 | C24: #VALUE! | D24: {=_FV(DataRT!$C24,"Currency")} | E24: {=_FV(DataRT!$C24,"Last trade time",TRUE)} | F24: {=_FV(DataRT!$C24,"Previous close",TRUE)} | G24: {=IFERROR(_FV(DataRT!$C24,"Open"),DataRT!$F24)} | H24: {=_FV(DataRT!$C24,"Price")} | I24: {=IFERROR(_FV(DataRT!$C24,"Low"),0)} | J24: {=IFERROR(_FV(DataRT!$C24,"High"),0)} | K24: {=IFERROR(_FV(DataRT!$C24,"P/E",TRUE),99)} | L24: {=_FV(DataRT!$C24,"Change")} | M24: {=_FV(DataRT!$C24,"Change (%)",TRUE)} | N24: {=_FV(DataRT!$C24,"52 week low",TRUE)} | O24: {=_FV(DataRT!$C24,"52 week high",TRUE)} | P24: {=_FV(DataRT!$C24,"Volume")} | Q24: {=_FV(DataRT!$C24,"Volume average",TRUE)} | R24: {=_FV(DataRT!$C24,"Beta")} | T24: V | U24: {=_FV(DataRT!$C24,"Exchange abbreviation",TRUE)} | V24: =IFERROR(DataRT!$P24/DataRT!$Q24,1) | X24: =_xlfn.XLOOKUP(DataRT!$A24,TickerList!$G23:$G117,TickerList!L23:L117) | Y24: =_xlfn.XLOOKUP(DataRT!$A24,TickerList!$G23:$G117,TickerList!M23:M117) | Z24: =_xlfn.XLOOKUP(DataRT!$A24,TickerList!$G23:$G117,TickerList!N23:N117) | AA24: =_xlfn.XLOOKUP(DataRT!$A24,TickerList!$G23:$G117,TickerList!O23:O117) | AB24: 0.0001 | AC24: 0.003 | AD24: 56.25 | AE24: =_xlfn.LET(_xlpm.New1YT,DataRT!$X24, _xlpm.Old1YT,IF(ISNUMBER(DataRT!$AD24),DataRT!$AD24,VALUE(LEFT(DataRT!$AD24,FIND("/",DataRT!$AD24,1)-1))), IF(OR(DataRT!$X24=0,_xlpm.Old1YT=0),0,(_xlpm.New1YT-_xlpm.Old1YT)/_xlpm.Old1YT)) | AF24: =TEXT(DataRT!$X24,"#,#0.00")&" < "&DataRT!$AD24
A25: {=_xlfn.SINGLE(DataRT!$S$3:$S$96)&_FV(DataRT!$C25,"Ticker symbol",TRUE)} | B25: =D99 | C25: #VALUE! | D25: {=_FV(DataRT!$C25,"Currency")} | E25: {=_FV(DataRT!$C25,"Last trade time",TRUE)} | F25: {=_FV(DataRT!$C25,"Previous close",TRUE)} | G25: {=IFERROR(_FV(DataRT!$C25,"Open"),DataRT!$F25)} | H25: {=_FV(DataRT!$C25,"Price")} | I25: {=IFERROR(_FV(DataRT!$C25,"Low"),0)} | J25: {=IFERROR(_FV(DataRT!$C25,"High"),0)} | K25: {=IFERROR(_FV(DataRT!$C25,"P/E",TRUE),99)} | L25: {=_FV(DataRT!$C25,"Change")} | M25: {=_FV(DataRT!$C25,"Change (%)",TRUE)} | N25: {=_FV(DataRT!$C25,"52 week low",TRUE)} | O25: {=_FV(DataRT!$C25,"52 week high",TRUE)} | P25: {=_FV(DataRT!$C25,"Volume")} | Q25: {=_FV(DataRT!$C25,"Volume average",TRUE)} | R25: {=_FV(DataRT!$C25,"Beta")} | T25: V | U25: {=_FV(DataRT!$C25,"Exchange abbreviation",TRUE)} | V25: =IFERROR(DataRT!$P25/DataRT!$Q25,1) | X25: =_xlfn.XLOOKUP(DataRT!$A25,TickerList!$G24:$G118,TickerList!L24:L118) | Y25: =_xlfn.XLOOKUP(DataRT!$A25,TickerList!$G24:$G118,TickerList!M24:M118) | Z25: =_xlfn.XLOOKUP(DataRT!$A25,TickerList!$G24:$G118,TickerList!N24:N118) | AA25: =_xlfn.XLOOKUP(DataRT!$A25,TickerList!$G24:$G118,TickerList!O24:O118) | AB25: 0.0001 | AC25: 0.003 | AD25: 21.47/20.14 | AE25: =_xlfn.LET(_xlpm.New1YT,DataRT!$X25, _xlpm.Old1YT,IF(ISNUMBER(DataRT!$AD25),DataRT!$AD25,VALUE(LEFT(DataRT!$AD25,FIND("/",DataRT!$AD25,1)-1))), IF(OR(DataRT!$X25=0,_xlpm.Old1YT=0),0,(_xlpm.New1YT-_xlpm.Old1YT)/_xlpm.Old1YT)) | AF25: =TEXT(DataRT!$X25,"#,#0.00")&" < "&DataRT!$AD25
A26: {=_xlfn.SINGLE(DataRT!$S$3:$S$96)&_FV(DataRT!$C26,"Ticker symbol",TRUE)} | B26: =D99 | C26: #VALUE! | D26: {=_FV(DataRT!$C26,"Currency")} | E26: {=_FV(DataRT!$C26,"Last trade time",TRUE)} | F26: {=_FV(DataRT!$C26,"Previous close",TRUE)} | G26: {=IFERROR(_FV(DataRT!$C26,"Open"),DataRT!$F26)} | H26: {=_FV(DataRT!$C26,"Price")} | I26: {=IFERROR(_FV(DataRT!$C26,"Low"),0)} | J26: {=IFERROR(_FV(DataRT!$C26,"High"),0)} | K26: {=IFERROR(_FV(DataRT!$C26,"P/E",TRUE),99)} | L26: {=_FV(DataRT!$C26,"Change")} | M26: {=_FV(DataRT!$C26,"Change (%)",TRUE)} | N26: {=_FV(DataRT!$C26,"52 week low",TRUE)} | O26: {=_FV(DataRT!$C26,"52 week high",TRUE)} | P26: {=_FV(DataRT!$C26,"Volume")} | Q26: {=_FV(DataRT!$C26,"Volume average",TRUE)} | R26: {=_FV(DataRT!$C26,"Beta")} | T26: V | U26: {=_FV(DataRT!$C26,"Exchange abbreviation",TRUE)} | V26: =IFERROR(DataRT!$P26/DataRT!$Q26,1) | X26: =_xlfn.XLOOKUP(DataRT!$A26,TickerList!$G25:$G119,TickerList!L25:L119) | Y26: =_xlfn.XLOOKUP(DataRT!$A26,TickerList!$G25:$G119,TickerList!M25:M119) | Z26: =_xlfn.XLOOKUP(DataRT!$A26,TickerList!$G25:$G119,TickerList!N25:N119) | AA26: =_xlfn.XLOOKUP(DataRT!$A26,TickerList!$G25:$G119,TickerList!O25:O119) | AB26: 0.0001 | AC26: 0.003 | AD26: 36.26 | AE26: =_xlfn.LET(_xlpm.New1YT,DataRT!$X26, _xlpm.Old1YT,IF(ISNUMBER(DataRT!$AD26),DataRT!$AD26,VALUE(LEFT(DataRT!$AD26,FIND("/",DataRT!$AD26,1)-1))), IF(OR(DataRT!$X26=0,_xlpm.Old1YT=0),0,(_xlpm.New1YT-_xlpm.Old1YT)/_xlpm.Old1YT)) | AF26: =TEXT(DataRT!$X26,"#,#0.00")&" < "&DataRT!$AD26
A27: {=_xlfn.SINGLE(DataRT!$S$3:$S$96)&_FV(DataRT!$C27,"Ticker symbol",TRUE)} | B27: =D101/100 | C27: #VALUE! | D27: {=_FV(DataRT!$C27,"Currency")} | E27: {=_FV(DataRT!$C27,"Last trade time",TRUE)} | F27: {=_FV(DataRT!$C27,"Previous close",TRUE)} | G27: {=IFERROR(_FV(DataRT!$C27,"Open"),DataRT!$F27)} | H27: {=_FV(DataRT!$C27,"Price")} | I27: {=IFERROR(_FV(DataRT!$C27,"Low"),0)} | J27: {=IFERROR(_FV(DataRT!$C27,"High"),0)} | K27: {=IFERROR(_FV(DataRT!$C27,"P/E",TRUE),99)} | L27: {=_FV(DataRT!$C27,"Change")} | M27: {=_FV(DataRT!$C27,"Change (%)",TRUE)} | N27: {=_FV(DataRT!$C27,"52 week low",TRUE)} | O27: {=_FV(DataRT!$C27,"52 week high",TRUE)} | P27: {=_FV(DataRT!$C27,"Volume")} | Q27: {=_FV(DataRT!$C27,"Volume average",TRUE)} | R27: {=_FV(DataRT!$C27,"Beta")} | T27: V | U27: {=_FV(DataRT!$C27,"Exchange abbreviation",TRUE)} | V27: =IFERROR(DataRT!$P27/DataRT!$Q27,1) | X27: =_xlfn.XLOOKUP(DataRT!$A27,TickerList!$G26:$G120,TickerList!L26:L120) | Y27: =_xlfn.XLOOKUP(DataRT!$A27,TickerList!$G26:$G120,TickerList!M26:M120) | Z27: =_xlfn.XLOOKUP(DataRT!$A27,TickerList!$G26:$G120,TickerList!N26:N120) | AA27: =_xlfn.XLOOKUP(DataRT!$A27,TickerList!$G26:$G120,TickerList!O26:O120) | AC27: 0.003 | AD27: 393.1 | AE27: =_xlfn.LET(_xlpm.New1YT,DataRT!$X27, _xlpm.Old1YT,IF(ISNUMBER(DataRT!$AD27),DataRT!$AD27,VALUE(LEFT(DataRT!$AD27,FIND("/",DataRT!$AD27,1)-1))), IF(OR(DataRT!$X27=0,_xlpm.Old1YT=0),0,(_xlpm.New1YT-_xlpm.Old1YT)/_xlpm.Old1YT)) | AF27: =TEXT(DataRT!$X27,"#,#0.00")&" < "&DataRT!$AD27
A28: {=_xlfn.SINGLE(DataRT!$S$3:$S$96)&_FV(DataRT!$C28,"Ticker symbol",TRUE)} | B28: =D99 | C28: #VALUE! | D28: {=_FV(DataRT!$C28,"Currency")} | E28: {=_FV(DataRT!$C28,"Last trade time",TRUE)} | F28: {=_FV(DataRT!$C28,"Previous close",TRUE)} | G28: {=IFERROR(_FV(DataRT!$C28,"Open"),DataRT!$F28)} | H28: {=_FV(DataRT!$C28,"Price")} | I28: {=IFERROR(_FV(DataRT!$C28,"Low"),0)} | J28: {=IFERROR(_FV(DataRT!$C28,"High"),0)} | K28: {=IFERROR(_FV(DataRT!$C28,"P/E",TRUE),99)} | L28: {=_FV(DataRT!$C28,"Change")} | M28: {=_FV(DataRT!$C28,"Change (%)",TRUE)} | N28: {=_FV(DataRT!$C28,"52 week low",TRUE)} | O28: {=_FV(DataRT!$C28,"52 week high",TRUE)} | P28: {=_FV(DataRT!$C28,"Volume")} | Q28: {=_FV(DataRT!$C28,"Volume average",TRUE)} | R28: {=_FV(DataRT!$C28,"Beta")} | T28: V | U28: {=_FV(DataRT!$C28,"Exchange abbreviation",TRUE)} | V28: =IFERROR(DataRT!$P28/DataRT!$Q28,1) | X28: =_xlfn.XLOOKUP(DataRT!$A28,TickerList!$G27:$G121,TickerList!L27:L121) | Y28: =_xlfn.XLOOKUP(DataRT!$A28,TickerList!$G27:$G121,TickerList!M27:M121) | Z28: =_xlfn.XLOOKUP(DataRT!$A28,TickerList!$G27:$G121,TickerList!N27:N121) | AA28: =_xlfn.XLOOKUP(DataRT!$A28,TickerList!$G27:$G121,TickerList!O27:O121) | AB28: 0.0001 | AC28: 0.003 | AD28: 66.5 | AE28: =_xlfn.LET(_xlpm.New1YT,DataRT!$X28, _xlpm.Old1YT,IF(ISNUMBER(DataRT!$AD28),DataRT!$AD28,VALUE(LEFT(DataRT!$AD28,FIND("/",DataRT!$AD28,1)-1))), IF(OR(DataRT!$X28=0,_xlpm.Old1YT=0),0,(_xlpm.New1YT-_xlpm.Old1YT)/_xlpm.Old1YT)) | AF28: =TEXT(DataRT!$X28,"#,#0.00")&" < "&DataRT!$AD28
A29: {=_xlfn.SINGLE(DataRT!$S$3:$S$96)&_FV(DataRT!$C29,"Ticker symbol",TRUE)} | B29: =D99 | C29: #VALUE! | D29: {=_FV(DataRT!$C29,"Currency")} | E29: {=_FV(DataRT!$C29,"Last trade time",TRUE)} | F29: {=_FV(DataRT!$C29,"Previous close",TRUE)} | G29: {=IFERROR(_FV(DataRT!$C29,"Open"),DataRT!$F29)} | H29: {=_FV(DataRT!$C29,"Price")} | I29: {=IFERROR(_FV(DataRT!$C29,"Low"),0)} | J29: {=IFERROR(_FV(DataRT!$C29,"High"),0)} | K29: {=IFERROR(_FV(DataRT!$C29,"P/E",TRUE),99)} | L29: {=_FV(DataRT!$C29,"Change")} | M29: {=_FV(DataRT!$C29,"Change (%)",TRUE)} | N29: {=_FV(DataRT!$C29,"52 week low",TRUE)} | O29: {=_FV(DataRT!$C29,"52 week high",TRUE)} | P29: {=_FV(DataRT!$C29,"Volume")} | Q29: {=_FV(DataRT!$C29,"Volume average",TRUE)} | R29: {=_FV(DataRT!$C29,"Beta")} | T29: V | U29: {=_FV(DataRT!$C29,"Exchange abbreviation",TRUE)} | V29: =IFERROR(DataRT!$P29/DataRT!$Q29,1) | X29: =_xlfn.XLOOKUP(DataRT!$A29,TickerList!$G28:$G122,TickerList!L28:L122) | Y29: =_xlfn.XLOOKUP(DataRT!$A29,TickerList!$G28:$G122,TickerList!M28:M122) | Z29: =_xlfn.XLOOKUP(DataRT!$A29,TickerList!$G28:$G122,TickerList!N28:N122) | AA29: =_xlfn.XLOOKUP(DataRT!$A29,TickerList!$G28:$G122,TickerList!O28:O122) | AB29: 0.0001 | AC29: 0.003 | AD29: 15.5 | AE29: =_xlfn.LET(_xlpm.New1YT,DataRT!$X29, _xlpm.Old1YT,IF(ISNUMBER(DataRT!$AD29),DataRT!$AD29,VALUE(LEFT(DataRT!$AD29,FIND("/",DataRT!$AD29,1)-1))), IF(OR(DataRT!$X29=0,_xlpm.Old1YT=0),0,(_xlpm.New1YT-_xlpm.Old1YT)/_xlpm.Old1YT)) | AF29: =TEXT(DataRT!$X29,"#,#0.00")&" < "&DataRT!$AD29
A30: {=_xlfn.SINGLE(DataRT!$S$3:$S$96)&_FV(DataRT!$C30,"Ticker symbol",TRUE)} | B30: =D99 | C30: #VALUE! | D30: {=_FV(DataRT!$C30,"Currency")} | E30: {=_FV(DataRT!$C30,"Last trade time",TRUE)} | F30: {=_FV(DataRT!$C30,"Previous close",TRUE)} | G30: {=IFERROR(_FV(DataRT!$C30,"Open"),DataRT!$F30)} | H30: {=_FV(DataRT!$C30,"Price")} | I30: {=IFERROR(_FV(DataRT!$C30,"Low"),0)} | J30: {=IFERROR(_FV(DataRT!$C30,"High"),0)} | K30: {=IFERROR(_FV(DataRT!$C30,"P/E",TRUE),99)} | L30: {=_FV(DataRT!$C30,"Change")} | M30: {=_FV(DataRT!$C30,"Change (%)",TRUE)} | N30: {=_FV(DataRT!$C30,"52 week low",TRUE)} | O30: {=_FV(DataRT!$C30,"52 week high",TRUE)} | P30: {=_FV(DataRT!$C30,"Volume")} | Q30: {=_FV(DataRT!$C30,"Volume average",TRUE)} | R30: {=_FV(DataRT!$C30,"Beta")} | T30: V | U30: {=_FV(DataRT!$C30,"Exchange abbreviation",TRUE)} | V30: =IFERROR(DataRT!$P30/DataRT!$Q30,1) | X30: =_xlfn.XLOOKUP(DataRT!$A30,TickerList!$G29:$G123,TickerList!L29:L123) | Y30: =_xlfn.XLOOKUP(DataRT!$A30,TickerList!$G29:$G123,TickerList!M29:M123) | Z30: =_xlfn.XLOOKUP(DataRT!$A30,TickerList!$G29:$G123,TickerList!N29:N123) | AA30: =_xlfn.XLOOKUP(DataRT!$A30,TickerList!$G29:$G123,TickerList!O29:O123) | AB30: 0.0001 | AC30: 0.003 | AD30: 4.62 | AE30: =_xlfn.LET(_xlpm.New1YT,DataRT!$X30, _xlpm.Old1YT,IF(ISNUMBER(DataRT!$AD30),DataRT!$AD30,VALUE(LEFT(DataRT!$AD30,FIND("/",DataRT!$AD30,1)-1))), IF(OR(DataRT!$X30=0,_xlpm.Old1YT=0),0,(_xlpm.New1YT-_xlpm.Old1YT)/_xlpm.Old1YT)) | AF30: =TEXT(DataRT!$X30,"#,#0.00")&" < "&DataRT!$AD30
A31: {=_xlfn.SINGLE(DataRT!$S$3:$S$96)&_FV(DataRT!$C31,"Ticker symbol",TRUE)} | B31: =D99 | C31: #VALUE! | D31: {=_FV(DataRT!$C31,"Currency")} | E31: {=_FV(DataRT!$C31,"Last trade time",TRUE)} | F31: {=_FV(DataRT!$C31,"Previous close",TRUE)} | G31: {=IFERROR(_FV(DataRT!$C31,"Open"),DataRT!$F31)} | H31: {=_FV(DataRT!$C31,"Price")} | I31: {=IFERROR(_FV(DataRT!$C31,"Low"),0)} | J31: {=IFERROR(_FV(DataRT!$C31,"High"),0)} | K31: {=IFERROR(_FV(DataRT!$C31,"P/E",TRUE),99)} | L31: {=_FV(DataRT!$C31,"Change")} | M31: {=_FV(DataRT!$C31,"Change (%)",TRUE)} | N31: {=_FV(DataRT!$C31,"52 week low",TRUE)} | O31: {=_FV(DataRT!$C31,"52 week high",TRUE)} | P31: {=_FV(DataRT!$C31,"Volume")} | Q31: {=_FV(DataRT!$C31,"Volume average",TRUE)} | R31: {=_FV(DataRT!$C31,"Beta")} | T31: V | U31: {=_FV(DataRT!$C31,"Exchange abbreviation",TRUE)} | V31: =IFERROR(DataRT!$P31/DataRT!$Q31,1) | X31: =_xlfn.XLOOKUP(DataRT!$A31,TickerList!$G30:$G124,TickerList!L30:L124) | Y31: =_xlfn.XLOOKUP(DataRT!$A31,TickerList!$G30:$G124,TickerList!M30:M124) | Z31: =_xlfn.XLOOKUP(DataRT!$A31,TickerList!$G30:$G124,TickerList!N30:N124) | AA31: =_xlfn.XLOOKUP(DataRT!$A31,TickerList!$G30:$G124,TickerList!O30:O124) | AB31: 0.0001 | AC31: 0.003 | AD31: 99.83 | AE31: =_xlfn.LET(_xlpm.New1YT,DataRT!$X31, _xlpm.Old1YT,IF(ISNUMBER(DataRT!$AD31),DataRT!$AD31,VALUE(LEFT(DataRT!$AD31,FIND("/",DataRT!$AD31,1)-1))), IF(OR(DataRT!$X31=0,_xlpm.Old1YT=0),0,(_xlpm.New1YT-_xlpm.Old1YT)/_xlpm.Old1YT)) | AF31: =TEXT(DataRT!$X31,"#,#0.00")&" < "&DataRT!$AD31
A32: {=_xlfn.SINGLE(DataRT!$S$3:$S$96)&_FV(DataRT!$C32,"Ticker symbol",TRUE)} | B32: =D99 | C32: #VALUE! | D32: {=_FV(DataRT!$C32,"Currency")} | E32: {=_FV(DataRT!$C32,"Last trade time",TRUE)} | F32: {=_FV(DataRT!$C32,"Previous close",TRUE)} | G32: {=IFERROR(_FV(DataRT!$C32,"Open"),DataRT!$F32)} | H32: {=_FV(DataRT!$C32,"Price")} | I32: {=IFERROR(_FV(DataRT!$C32,"Low"),0)} | J32: {=IFERROR(_FV(DataRT!$C32,"High"),0)} | K32: {=IFERROR(_FV(DataRT!$C32,"P/E",TRUE),99)} | L32: {=_FV(DataRT!$C32,"Change")} | M32: {=_FV(DataRT!$C32,"Change (%)",TRUE)} | N32: {=_FV(DataRT!$C32,"52 week low",TRUE)} | O32: {=_FV(DataRT!$C32,"52 week high",TRUE)} | P32: {=_FV(DataRT!$C32,"Volume")} | Q32: {=_FV(DataRT!$C32,"Volume average",TRUE)} | R32: {=_FV(DataRT!$C32,"Beta")} | T32: V | U32: {=_FV(DataRT!$C32,"Exchange abbreviation",TRUE)} | V32: =IFERROR(DataRT!$P32/DataRT!$Q32,1) | X32: =_xlfn.XLOOKUP(DataRT!$A32,TickerList!$G31:$G125,TickerList!L31:L125) | Y32: =_xlfn.XLOOKUP(DataRT!$A32,TickerList!$G31:$G125,TickerList!M31:M125) | Z32: =_xlfn.XLOOKUP(DataRT!$A32,TickerList!$G31:$G125,TickerList!N31:N125) | AA32: =_xlfn.XLOOKUP(DataRT!$A32,TickerList!$G31:$G125,TickerList!O31:O125) | AB32: 0.0001 | AC32: 0.003 | AD32: 505.94 | AE32: =_xlfn.LET(_xlpm.New1YT,DataRT!$X32, _xlpm.Old1YT,IF(ISNUMBER(DataRT!$AD32),DataRT!$AD32,VALUE(LEFT(DataRT!$AD32,FIND("/",DataRT!$AD32,1)-1))), IF(OR(DataRT!$X32=0,_xlpm.Old1YT=0),0,(_xlpm.New1YT-_xlpm.Old1YT)/_xlpm.Old1YT)) | AF32: =TEXT(DataRT!$X32,"#,#0.00")&" < "&DataRT!$AD32
A33: {=_xlfn.SINGLE(DataRT!$S$3:$S$96)&_FV(DataRT!$C33,"Ticker symbol",TRUE)} | B33: =D99 | C33: #VALUE! | D33: {=_FV(DataRT!$C33,"Currency")} | E33: {=_FV(DataRT!$C33,"Last trade time",TRUE)} | F33: {=_FV(DataRT!$C33,"Previous close",TRUE)} | G33: {=IFERROR(_FV(DataRT!$C33,"Open"),DataRT!$F33)} | H33: {=_FV(DataRT!$C33,"Price")} | I33: {=IFERROR(_FV(DataRT!$C33,"Low"),0)} | J33: {=IFERROR(_FV(DataRT!$C33,"High"),0)} | K33: {=IFERROR(_FV(DataRT!$C33,"P/E",TRUE),99)} | L33: {=_FV(DataRT!$C33,"Change")} | M33: {=_FV(DataRT!$C33,"Change (%)",TRUE)} | N33: {=_FV(DataRT!$C33,"52 week low",TRUE)} | O33: {=_FV(DataRT!$C33,"52 week high",TRUE)} | P33: {=_FV(DataRT!$C33,"Volume")} | Q33: {=_FV(DataRT!$C33,"Volume average",TRUE)} | R33: {=_FV(DataRT!$C33,"Beta")} | T33: V | U33: {=_FV(DataRT!$C33,"Exchange abbreviation",TRUE)} | V33: =IFERROR(DataRT!$P33/DataRT!$Q33,1) | X33: =_xlfn.XLOOKUP(DataRT!$A33,TickerList!$G32:$G126,TickerList!L32:L126) | Y33: =_xlfn.XLOOKUP(DataRT!$A33,TickerList!$G32:$G126,TickerList!M32:M126) | Z33: =_xlfn.XLOOKUP(DataRT!$A33,TickerList!$G32:$G126,TickerList!N32:N126) | AA33: =_xlfn.XLOOKUP(DataRT!$A33,TickerList!$G32:$G126,TickerList!O32:O126) | AB33: 0.0001 | AC33: 0.003 | AD33: 81.10/84.6 | AE33: =_xlfn.LET(_xlpm.New1YT,DataRT!$X33, _xlpm.Old1YT,IF(ISNUMBER(DataRT!$AD33),DataRT!$AD33,VALUE(LEFT(DataRT!$AD33,FIND("/",DataRT!$AD33,1)-1))), IF(OR(DataRT!$X33=0,_xlpm.Old1YT=0),0,(_xlpm.New1YT-_xlpm.Old1YT)/_xlpm.Old1YT)) | AF33: =TEXT(DataRT!$X33,"#,#0.00")&" < "&DataRT!$AD33
A34: {=_xlfn.SINGLE(DataRT!$S$3:$S$96)&_FV(DataRT!$C34,"Ticker symbol",TRUE)} | B34: =D99 | C34: #VALUE! | D34: {=_FV(DataRT!$C34,"Currency")} | E34: {=_FV(DataRT!$C34,"Last trade time",TRUE)} | F34: {=_FV(DataRT!$C34,"Previous close",TRUE)} | G34: {=IFERROR(_FV(DataRT!$C34,"Open"),DataRT!$F34)} | H34: {=_FV(DataRT!$C34,"Price")} | I34: {=IFERROR(_FV(DataRT!$C34,"Low"),0)} | J34: {=IFERROR(_FV(DataRT!$C34,"High"),0)} | K34: {=IFERROR(_FV(DataRT!$C34,"P/E",TRUE),99)} | L34: {=_FV(DataRT!$C34,"Change")} | M34: {=_FV(DataRT!$C34,"Change (%)",TRUE)} | N34: {=_FV(DataRT!$C34,"52 week low",TRUE)} | O34: {=_FV(DataRT!$C34,"52 week high",TRUE)} | P34: {=_FV(DataRT!$C34,"Volume")} | Q34: {=_FV(DataRT!$C34,"Volume average",TRUE)} | R34: {=_FV(DataRT!$C34,"Beta")} | T34: V | U34: {=_FV(DataRT!$C34,"Exchange abbreviation",TRUE)} | V34: =IFERROR(DataRT!$P34/DataRT!$Q34,1) | X34: =_xlfn.XLOOKUP(DataRT!$A34,TickerList!$G33:$G127,TickerList!L33:L127) | Y34: =_xlfn.XLOOKUP(DataRT!$A34,TickerList!$G33:$G127,TickerList!M33:M127) | Z34: =_xlfn.XLOOKUP(DataRT!$A34,TickerList!$G33:$G127,TickerList!N33:N127) | AA34: =_xlfn.XLOOKUP(DataRT!$A34,TickerList!$G33:$G127,TickerList!O33:O127) | AB34: 0.0001 | AC34: 0.003 | AD34: 59.51 | AE34: =_xlfn.LET(_xlpm.New1YT,DataRT!$X34, _xlpm.Old1YT,IF(ISNUMBER(DataRT!$AD34),DataRT!$AD34,VALUE(LEFT(DataRT!$AD34,FIND("/",DataRT!$AD34,1)-1))), IF(OR(DataRT!$X34=0,_xlpm.Old1YT=0),0,(_xlpm.New1YT-_xlpm.Old1YT)/_xlpm.Old1YT)) | AF34: =TEXT(DataRT!$X34,"#,#0.00")&" < "&DataRT!$AD34
A35: {=_xlfn.SINGLE(DataRT!$S$3:$S$96)&_FV(DataRT!$C35,"Ticker symbol",TRUE)} | B35: =D99 | C35: #VALUE! | D35: {=_FV(DataRT!$C35,"Currency")} | E35: {=_FV(DataRT!$C35,"Last trade time",TRUE)} | F35: {=_FV(DataRT!$C35,"Previous close",TRUE)} | G35: {=IFERROR(_FV(DataRT!$C35,"Open"),DataRT!$F35)} | H35: {=_FV(DataRT!$C35,"Price")} | I35: {=IFERROR(_FV(DataRT!$C35,"Low"),0)} | J35: {=IFERROR(_FV(DataRT!$C35,"High"),0)} | K35: {=IFERROR(_FV(DataRT!$C35,"P/E",TRUE),99)} | L35: {=_FV(DataRT!$C35,"Change")} | M35: {=_FV(DataRT!$C35,"Change (%)",TRUE)} | N35: {=_FV(DataRT!$C35,"52 week low",TRUE)} | O35: {=_FV(DataRT!$C35,"52 week high",TRUE)} | P35: {=_FV(DataRT!$C35,"Volume")} | Q35: {=_FV(DataRT!$C35,"Volume average",TRUE)} | R35: {=_FV(DataRT!$C35,"Beta")} | T35: V | U35: {=_FV(DataRT!$C35,"Exchange abbreviation",TRUE)} | V35: =IFERROR(DataRT!$P35/DataRT!$Q35,1) | X35: =_xlfn.XLOOKUP(DataRT!$A35,TickerList!$G34:$G128,TickerList!L34:L128) | Y35: =_xlfn.XLOOKUP(DataRT!$A35,TickerList!$G34:$G128,TickerList!M34:M128) | Z35: =_xlfn.XLOOKUP(DataRT!$A35,TickerList!$G34:$G128,TickerList!N34:N128) | AA35: =_xlfn.XLOOKUP(DataRT!$A35,TickerList!$G34:$G128,TickerList!O34:O128) | AB35: 0.0001 | AC35: 0.003 | AD35: 764.34 | AE35: =_xlfn.LET(_xlpm.New1YT,DataRT!$X35, _xlpm.Old1YT,IF(ISNUMBER(DataRT!$AD35),DataRT!$AD35,VALUE(LEFT(DataRT!$AD35,FIND("/",DataRT!$AD35,1)-1))), IF(OR(DataRT!$X35=0,_xlpm.Old1YT=0),0,(_xlpm.New1YT-_xlpm.Old1YT)/_xlpm.Old1YT)) | AF35: =TEXT(DataRT!$X35,"#,#0.00")&" < "&DataRT!$AD35
A36: {=_xlfn.SINGLE(DataRT!$S$3:$S$96)&_FV(DataRT!$C36,"Ticker symbol",TRUE)} | B36: =D99 | C36: #VALUE! | D36: {=_FV(DataRT!$C36,"Currency")} | E36: {=_FV(DataRT!$C36,"Last trade time",TRUE)} | F36: {=_FV(DataRT!$C36,"Previous close",TRUE)} | G36: {=IFERROR(_FV(DataRT!$C36,"Open"),DataRT!$F36)} | H36: {=_FV(DataRT!$C36,"Price")} | I36: {=IFERROR(_FV(DataRT!$C36,"Low"),0)} | J36: {=IFERROR(_FV(DataRT!$C36,"High"),0)} | K36: {=IFERROR(_FV(DataRT!$C36,"P/E",TRUE),99)} | L36: {=_FV(DataRT!$C36,"Change")} | M36: {=_FV(DataRT!$C36,"Change (%)",TRUE)} | N36: {=_FV(DataRT!$C36,"52 week low",TRUE)} | O36: {=_FV(DataRT!$C36,"52 week high",TRUE)} | P36: {=_FV(DataRT!$C36,"Volume")} | Q36: {=_FV(DataRT!$C36,"Volume average",TRUE)} | R36: {=_FV(DataRT!$C36,"Beta")} | T36: V | U36: {=_FV(DataRT!$C36,"Exchange abbreviation",TRUE)} | V36: =IFERROR(DataRT!$P36/DataRT!$Q36,1) | X36: =_xlfn.XLOOKUP(DataRT!$A36,TickerList!$G35:$G129,TickerList!L35:L129) | Y36: =_xlfn.XLOOKUP(DataRT!$A36,TickerList!$G35:$G129,TickerList!M35:M129) | Z36: =_xlfn.XLOOKUP(DataRT!$A36,TickerList!$G35:$G129,TickerList!N35:N129) | AA36: =_xlfn.XLOOKUP(DataRT!$A36,TickerList!$G35:$G129,TickerList!O35:O129) | AB36: 0.0001 | AC36: 0.003 | AD36: 31.5 | AE36: =_xlfn.LET(_xlpm.New1YT,DataRT!$X36, _xlpm.Old1YT,IF(ISNUMBER(DataRT!$AD36),DataRT!$AD36,VALUE(LEFT(DataRT!$AD36,FIND("/",DataRT!$AD36,1)-1))), IF(OR(DataRT!$X36=0,_xlpm.Old1YT=0),0,(_xlpm.New1YT-_xlpm.Old1YT)/_xlpm.Old1YT)) | AF36: =TEXT(DataRT!$X36,"#,#0.00")&" < "&DataRT!$AD36
A37: {=_xlfn.SINGLE(DataRT!$S$3:$S$96)&_FV(DataRT!$C37,"Ticker symbol",TRUE)} | B37: =D99 | C37: #VALUE! | D37: {=_FV(DataRT!$C37,"Currency")} | E37: {=_FV(DataRT!$C37,"Last trade time",TRUE)} | F37: {=_FV(DataRT!$C37,"Previous close",TRUE)} | G37: {=IFERROR(_FV(DataRT!$C37,"Open"),DataRT!$F37)} | H37: {=_FV(DataRT!$C37,"Price")} | I37: {=IFERROR(_FV(DataRT!$C37,"Low"),0)} | J37: {=IFERROR(_FV(DataRT!$C37,"High"),0)} | K37: {=IFERROR(_FV(DataRT!$C37,"P/E",TRUE),99)} | L37: {=_FV(DataRT!$C37,"Change")} | M37: {=_FV(DataRT!$C37,"Change (%)",TRUE)} | N37: {=_FV(DataRT!$C37,"52 week low",TRUE)} | O37: {=_FV(DataRT!$C37,"52 week high",TRUE)} | P37: {=_FV(DataRT!$C37,"Volume")} | Q37: {=_FV(DataRT!$C37,"Volume average",TRUE)} | R37: {=_FV(DataRT!$C37,"Beta")} | T37: V | U37: {=_FV(DataRT!$C37,"Exchange abbreviation",TRUE)} | V37: =IFERROR(DataRT!$P37/DataRT!$Q37,1) | X37: =_xlfn.XLOOKUP(DataRT!$A37,TickerList!$G36:$G130,TickerList!L36:L130) | Y37: =_xlfn.XLOOKUP(DataRT!$A37,TickerList!$G36:$G130,TickerList!M36:M130) | Z37: =_xlfn.XLOOKUP(DataRT!$A37,TickerList!$G36:$G130,TickerList!N36:N130) | AA37: =_xlfn.XLOOKUP(DataRT!$A37,TickerList!$G36:$G130,TickerList!O36:O130) | AB37: 0.0001 | AC37: 0.003 | AD37: 36.49 | AE37: =_xlfn.LET(_xlpm.New1YT,DataRT!$X37, _xlpm.Old1YT,IF(ISNUMBER(DataRT!$AD37),DataRT!$AD37,VALUE(LEFT(DataRT!$AD37,FIND("/",DataRT!$AD37,1)-1))), IF(OR(DataRT!$X37=0,_xlpm.Old1YT=0),0,(_xlpm.New1YT-_xlpm.Old1YT)/_xlpm.Old1YT)) | AF37: =TEXT(DataRT!$X37,"#,#0.00")&" < "&DataRT!$AD37
A38: {=_xlfn.SINGLE(DataRT!$S$3:$S$96)&_FV(DataRT!$C38,"Ticker symbol",TRUE)} | B38: =D99 | C38: #VALUE! | D38: {=_FV(DataRT!$C38,"Currency")} | E38: {=_FV(DataRT!$C38,"Last trade time",TRUE)} | F38: {=_FV(DataRT!$C38,"Previous close",TRUE)} | G38: {=IFERROR(_FV(DataRT!$C38,"Open"),DataRT!$F38)} | H38: {=_FV(DataRT!$C38,"Price")} | I38: {=IFERROR(_FV(DataRT!$C38,"Low"),0)} | J38: {=IFERROR(_FV(DataRT!$C38,"High"),0)} | K38: {=IFERROR(_FV(DataRT!$C38,"P/E",TRUE),99)} | L38: {=_FV(DataRT!$C38,"Change")} | M38: {=_FV(DataRT!$C38,"Change (%)",TRUE)} | N38: {=_FV(DataRT!$C38,"52 week low",TRUE)} | O38: {=_FV(DataRT!$C38,"52 week high",TRUE)} | P38: {=_FV(DataRT!$C38,"Volume")} | Q38: {=_FV(DataRT!$C38,"Volume average",TRUE)} | R38: {=_FV(DataRT!$C38,"Beta")} | T38: V | U38: {=_FV(DataRT!$C38,"Exchange abbreviation",TRUE)} | V38: =IFERROR(DataRT!$P38/DataRT!$Q38,1) | X38: =_xlfn.XLOOKUP(DataRT!$A38,TickerList!$G37:$G131,TickerList!L37:L131) | Y38: =_xlfn.XLOOKUP(DataRT!$A38,TickerList!$G37:$G131,TickerList!M37:M131) | Z38: =_xlfn.XLOOKUP(DataRT!$A38,TickerList!$G37:$G131,TickerList!N37:N131) | AA38: =_xlfn.XLOOKUP(DataRT!$A38,TickerList!$G37:$G131,TickerList!O37:O131) | AB38: 0.0001 | AC38: 0.003 | AD38: 15.17 | AE38: =_xlfn.LET(_xlpm.New1YT,DataRT!$X38, _xlpm.Old1YT,IF(ISNUMBER(DataRT!$AD38),DataRT!$AD38,VALUE(LEFT(DataRT!$AD38,FIND("/",DataRT!$AD38,1)-1))), IF(OR(DataRT!$X38=0,_xlpm.Old1YT=0),0,(_xlpm.New1YT-_xlpm.Old1YT)/_xlpm.Old1YT)) | AF38: =TEXT(DataRT!$X38,"#,#0.00")&" < "&DataRT!$AD38
A39: {=_xlfn.SINGLE(DataRT!$S$3:$S$96)&_FV(DataRT!$C39,"Ticker symbol",TRUE)} | B39: =D103 | C39: #VALUE! | D39: {=_FV(DataRT!$C39,"Currency")} | E39: {=_FV(DataRT!$C39,"Last trade time",TRUE)} | F39: {=_FV(DataRT!$C39,"Previous close",TRUE)} | G39: {=IFERROR(_FV(DataRT!$C39,"Open"),DataRT!$F39)} | H39: {=_FV(DataRT!$C39,"Price")} | I39: {=IFERROR(_FV(DataRT!$C39,"Low"),0)} | J39: {=IFERROR(_FV(DataRT!$C39,"High"),0)} | K39: {=IFERROR(_FV(DataRT!$C39,"P/E",TRUE),99)} | L39: {=_FV(DataRT!$C39,"Change")} | M39: {=_FV(DataRT!$C39,"Change (%)",TRUE)} | N39: {=_FV(DataRT!$C39,"52 week low",TRUE)} | O39: {=_FV(DataRT!$C39,"52 week high",TRUE)} | P39: {=_FV(DataRT!$C39,"Volume")} | Q39: {=_FV(DataRT!$C39,"Volume average",TRUE)} | R39: {=_FV(DataRT!$C39,"Beta")} | T39: V | U39: {=_FV(DataRT!$C39,"Exchange abbreviation",TRUE)} | V39: =IFERROR(DataRT!$P39/DataRT!$Q39,1) | X39: =_xlfn.XLOOKUP(DataRT!$A39,TickerList!$G38:$G132,TickerList!L38:L132) | Y39: =_xlfn.XLOOKUP(DataRT!$A39,TickerList!$G38:$G132,TickerList!M38:M132) | Z39: =_xlfn.XLOOKUP(DataRT!$A39,TickerList!$G38:$G132,TickerList!N38:N132) | AA39: =_xlfn.XLOOKUP(DataRT!$A39,TickerList!$G38:$G132,TickerList!O38:O132) | AB39: 0.0001 | AC39: 0.003 | AD39: 4.3 | AE39: =_xlfn.LET(_xlpm.New1YT,DataRT!$X39, _xlpm.Old1YT,IF(ISNUMBER(DataRT!$AD39),DataRT!$AD39,VALUE(LEFT(DataRT!$AD39,FIND("/",DataRT!$AD39,1)-1))), IF(OR(DataRT!$X39=0,_xlpm.Old1YT=0),0,(_xlpm.New1YT-_xlpm.Old1YT)/_xlpm.Old1YT)) | AF39: =TEXT(DataRT!$X39,"#,#0.00")&" < "&DataRT!$AD39
A40: {=_xlfn.SINGLE(DataRT!$S$3:$S$96)&_FV(DataRT!$C40,"Ticker symbol",TRUE)} | B40: =D99 | C40: #VALUE! | D40: {=_FV(DataRT!$C40,"Currency")} | E40: {=_FV(DataRT!$C40,"Last trade time",TRUE)} | F40: {=_FV(DataRT!$C40,"Previous close",TRUE)} | G40: {=IFERROR(_FV(DataRT!$C40,"Open"),DataRT!$F40)} | H40: {=_FV(DataRT!$C40,"Price")} | I40: {=IFERROR(_FV(DataRT!$C40,"Low"),0)} | J40: {=IFERROR(_FV(DataRT!$C40,"High"),0)} | K40: {=IFERROR(_FV(DataRT!$C40,"P/E",TRUE),99)} | L40: {=_FV(DataRT!$C40,"Change")} | M40: {=_FV(DataRT!$C40,"Change (%)",TRUE)} | N40: {=_FV(DataRT!$C40,"52 week low",TRUE)} | O40: {=_FV(DataRT!$C40,"52 week high",TRUE)} | P40: {=_FV(DataRT!$C40,"Volume")} | Q40: {=_FV(DataRT!$C40,"Volume average",TRUE)} | R40: {=_FV(DataRT!$C40,"Beta")} | T40: V | U40: {=_FV(DataRT!$C40,"Exchange abbreviation",TRUE)} | V40: =IFERROR(DataRT!$P40/DataRT!$Q40,1) | X40: =_xlfn.XLOOKUP(DataRT!$A40,TickerList!$G39:$G133,TickerList!L39:L133) | Y40: =_xlfn.XLOOKUP(DataRT!$A40,TickerList!$G39:$G133,TickerList!M39:M133) | Z40: =_xlfn.XLOOKUP(DataRT!$A40,TickerList!$G39:$G133,TickerList!N39:N133) | AA40: =_xlfn.XLOOKUP(DataRT!$A40,TickerList!$G39:$G133,TickerList!O39:O133) | AB40: 0.0001 | AC40: 0.003 | AD40: 0.56 | AE40: =_xlfn.LET(_xlpm.New1YT,DataRT!$X40, _xlpm.Old1YT,IF(ISNUMBER(DataRT!$AD40),DataRT!$AD40,VALUE(LEFT(DataRT!$AD40,FIND("/",DataRT!$AD40,1)-1))), IF(OR(DataRT!$X40=0,_xlpm.Old1YT=0),0,(_xlpm.New1YT-_xlpm.Old1YT)/_xlpm.Old1YT)) | AF40: =TEXT(DataRT!$X40,"#,#0.00")&" < "&DataRT!$AD40
...

Sheet TickerList
A1: Tickers | B1: =[1]Sheet1!B1 | C1: =[1]Sheet1!C1 | D1: =[1]Sheet1!D1 | E1: =[1]Sheet1!E1 | F1: Striped_Ticker | G1: Names | H1: Striped_Name | K1: Ordered?
A2: =[2]YData!A2 | B2: =[2]YData!B2 | C2: =VALUE([2]YData!C2) | D2: =[2]YData!D2 | E2: =[2]YData!E2 | F2: =_xlfn.LET(_xlpm.Tick,A2,IFERROR(LEFT(_xlpm.Tick,FIND(".",_xlpm.Tick)-1),_xlpm.Tick)) | G2: AAPL | H2: {=_xlfn.IFS(OR(LEFT(G2,3)="SAF",LEFT(G2,3)="MVE"), RIGHT(G2,LEN(G2)-3), LEFT(G2,2)="JB", RIGHT(G2,LEN(G2)-2), TRUE, G2)} | K2: =_xlfn.LET(_xlpm.Tick,[2]YData!$A2,IFERROR(LEFT(_xlpm.Tick,FIND(".",_xlpm.Tick)-1),_xlpm.Tick)) | L2: {=IFERROR( INDEX(Dataload, MATCH(StripName, StripTick, 0), _xlfn.SEQUENCE(1, COLUMNS(Dataload))), "" )} | M2: 45971 | N2: Jan 29, 2026 | O2: 0.0038
A3: =[2]YData!A3 | B3: =[2]YData!B3 | C3: =VALUE([2]YData!C3) | D3: =[2]YData!D3 | E3: =[2]YData!E3 | F3: =_xlfn.LET(_xlpm.Tick,A3,IFERROR(LEFT(_xlpm.Tick,FIND(".",_xlpm.Tick)-1),_xlpm.Tick)) | G3: ADEA | H3: {=_xlfn.IFS(OR(LEFT(G3,3)="SAF",LEFT(G3,3)="MVE"), RIGHT(G3,LEN(G3)-3), LEFT(G3,2)="JB", RIGHT(G3,LEN(G3)-2), TRUE, G3)} | K3: =_xlfn.LET(_xlpm.Tick,[2]YData!$A3,IFERROR(LEFT(_xlpm.Tick,FIND(".",_xlpm.Tick)-1),_xlpm.Tick)) | L3: 20.66667 | M3: 45895 | N3: 0 | O3: 0.0117
A4: =[2]YData!A4 | B4: =[2]YData!B4 | C4: =VALUE([2]YData!C4) | D4: =[2]YData!D4 | E4: =[2]YData!E4 | F4: =_xlfn.LET(_xlpm.Tick,A4,IFERROR(LEFT(_xlpm.Tick,FIND(".",_xlpm.Tick)-1),_xlpm.Tick)) | G4: AET | H4: {=_xlfn.IFS(OR(LEFT(G4,3)="SAF",LEFT(G4,3)="MVE"), RIGHT(G4,LEN(G4)-3), LEFT(G4,2)="JB", RIGHT(G4,LEN(G4)-2), TRUE, G4)} | K4: =_xlfn.LET(_xlpm.Tick,[2]YData!$A4,IFERROR(LEFT(_xlpm.Tick,FIND(".",_xlpm.Tick)-1),_xlpm.Tick)) | L4: 96.66 | M4: 0 | N4: 0 | O4: 0
A5: =[2]YData!A5 | B5: =[2]YData!B5 | C5: =VALUE([2]YData!C5) | D5: =[2]YData!D5 | E5: =[2]YData!E5 | F5: =_xlfn.LET(_xlpm.Tick,A5,IFERROR(LEFT(_xlpm.Tick,FIND(".",_xlpm.Tick)-1),_xlpm.Tick)) | G5: AMZN | H5: {=_xlfn.IFS(OR(LEFT(G5,3)="SAF",LEFT(G5,3)="MVE"), RIGHT(G5,LEN(G5)-3), LEFT(G5,2)="JB", RIGHT(G5,LEN(G5)-2), TRUE, G5)} | K5: =_xlfn.LET(_xlpm.Tick,[2]YData!$A5,IFERROR(LEFT(_xlpm.Tick,FIND(".",_xlpm.Tick)-1),_xlpm.Tick)) | L5: 288.4241 | M5: 0 | N5: Oct 30, 2025 | O5: 0
