Workbook
Name Dataload: TickerList!$B$2:$E$75
Name SelRow: 5
Name SelRowNum: 5
Name StripName: TickerList!$H$2:$H$96
Name StripTick: TickerList!$F$2:$F$75
Name T_List: TickerList!$A$2:$A$75

Sheet ExtEntry
A1: =MAX(E3:E96) -> 45967.001 | B1: Today | E1: Today | F1: =NOW() -> 45967.058 | P1: 58505147 | X1: From DataLocal Sheet2
A2: Ticker_Symbol | B2: ExchR | C2: Company Name | D2: Currency | E2: Last trade time | F2: Close | G2: Open | H2: M-Price | I2: Low | J2: High | K2: P/E | L2: Change | M2: Change% | N2: 52_week_low | O2: 52_week_high | P2: Volume | Q2: Volume average | R2: Beta | S2: suffix | T2: Custody2 | U2: Exchange abbreviation | V2: V/VA | W2: Column1 | X2: 1YT | Y2: Ddate | Z2: EarningDate | AA2: RepDiv | AB2: Broker | AC2: Stamp | AD2: Old1YT | AE2: YTChange | AF2: Column2
A3: {=_xlfn.SINGLE(RTData[suffix])&_FV(RTData[[#This Row],[Company Name]],"Ticker symbol",TRUE)} -> AAPL | B3: =D99 -> 0.87001914 | C3: #VALUE! | D3: {=_FV(RTData[[#This Row],[Company Name]],"Currency")} -> USD | E3: {=_FV(RTData[[#This Row],[Company Name]],"Last trade time",TRUE)} -> 45967 | F3: {=_FV(RTData[[#This Row],[Company Name]],"Previous close",TRUE)} -> 270.04 | G3: {=_FV(RTData[[#This Row],[Company Name]],"Open")} -> 268.61 | H3: {=_FV(RTData[[#This Row],[Company Name]],"Price")} -> 270.14 | I3: {=_FV(RTData[[#This Row],[Company Name]],"Low")} -> 266.93 | J3: {=_FV(RTData[[#This Row],[Company Name]],"High")} -> 271.7 | K3: {=IFERROR(_FV(RTData[[#This Row],[Company Name]],"P/E",TRUE),99)} -> 36.3613 | L3: {=_FV(RTData[[#This Row],[Company Name]],"Change")} -> 0.1 | M3: {=_FV(RTData[[#This Row],[Company Name]],"Change (%)",TRUE)} -> 0.0003703 | N3: {=_FV(RTData[[#This Row],[Company Name]],"52 week low",TRUE)} -> 169.2101 | O3: {=_FV(RTData[[#This Row],[Company Name]],"52 week high",TRUE)} -> 277.32 | P3: {=_FV(RTData[[#This Row],[Company Name]],"Volume")} -> 43644546 | Q3: {=_FV(RTData[[#This Row],[Company Name]],"Volume average",TRUE)} -> 47864472 | R3: {=_FV(RTData[[#This Row],[Company Name]],"Beta")} -> 1.1077 | T3: V | U3: {=_FV(RTData[[#This Row],[Company Name]],"Exchange abbreviation",TRUE)} -> XNAS | V3: =IFERROR(RTData[[#This Row],[Volume]]/RTData[[#This Row],[Volume average]],1) -> 0.91183594 | X3: =_xlfn.XLOOKUP(RTData[[#This Row],[Ticker_Symbol]],TickerList!$G2:$G96,TickerList!L2:L96) -> 276.43097 | Y3: =_xlfn.XLOOKUP(RTData[[#This Row],[Ticker_Symbol]],TickerList!$G2:$G96,TickerList!M2:M96) -> 45971 | Z3: =_xlfn.XLOOKUP(RTData[[#This Row],[Ticker_Symbol]],TickerList!$G2:$G96,TickerList!N2:N96) -> Jan 29, 2026 | AA3: =_xlfn.XLOOKUP(RTData[[#This Row],[Ticker_Symbol]],TickerList!$G2:$G96,TickerList!O2:O96) -> 0.0038 | AB3: 0.0001 | AC3: 0.003 | AD3: 245.31 | AE3: =_xlfn.LET(_xlpm.New1YT,RTData[[#This Row],[1YT]], _xlpm.Old1YT,IF(ISNUMBER(RTData[[#This Row],[Old1YT]]),RTData[[#This Row],[Old1YT]],VALUE(LEFT(RTData[[#This Row],[Old1YT]],FIND("/",RTData[[#This Row],[Old1YT]],1)-1))), IF(OR(RTData[[#This Row],[1YT]]=0,_xlpm.Old1YT=0),0,(_xlpm.New1YT-_xlpm.Old1YT)/_xlpm.Old1YT)) -> 0.12686385 | AF3: =TEXT(RTData[[#This Row],[1YT]],"#,#0.00")&" < "&RTData[[#This Row],[Old1YT]] -> 276.43 < 245.31
A4: {=_xlfn.SINGLE(RTData[suffix])&_FV(RTData[[#This Row],[Company Name]],"Ticker symbol",TRUE)} -> ADEA | B4: =D99 -> 0.87001914 | C4: #VALUE! | D4: {=_FV(RTData[[#This Row],[Company Name]],"Currency")} -> USD | E4: {=_FV(RTData[[#This Row],[Company Name]],"Last trade time",TRUE)} -> 45966.95 | F4: {=_FV(RTData[[#This Row],[Company Name]],"Previous close",TRUE)} -> 12.75 | G4: {=_FV(RTData[[#This Row],[Company Name]],"Open")} -> 12.84 | H4: {=_FV(RTData[[#This Row],[Company Name]],"Price")} -> 13.78 | I4: {=_FV(RTData[[#This Row],[Company Name]],"Low")} -> 12.7 | J4: {=_FV(RTData[[#This Row],[Company Name]],"High")} -> 13.84 | K4: {=IFERROR(_FV(RTData[[#This Row],[Company Name]],"P/E",TRUE),99)} -> 21.2327 | L4: {=_FV(RTData[[#This Row],[Company Name]],"Change")} -> 1.03 | M4: {=_FV(RTData[[#This Row],[Company Name]],"Change (%)",TRUE)} -> 0.080784 | N4: {=_FV(RTData[[#This Row],[Company Name]],"52 week low",TRUE)} -> 10.59 | O4: {=_FV(RTData[[#This Row],[Company Name]],"52 week high",TRUE)} -> 18.25 | P4: {=_FV(RTData[[#This Row],[Company Name]],"Volume")} -> 1761241 | Q4: {=_FV(RTData[[#This Row],[Company Name]],"Volume average",TRUE)} -> 681700 | R4: {=_FV(RTData[[#This Row],[Company Name]],"Beta")} -> 2.4069 | T4: V | U4: {=_FV(RTData[[#This Row],[Company Name]],"Exchange abbreviation",TRUE)} -> XNAS | V4: =IFERROR(RTData[[#This Row],[Volume]]/RTData[[#This Row],[Volume average]],1) -> 2.5836013 | X4: =_xlfn.XLOOKUP(RTData[[#This Row],[Ticker_Symbol]],TickerList!$G3:$G97,TickerList!L3:L97) -> 20.66667 | Y4: =_xlfn.XLOOKUP(RTData[[#This Row],[Ticker_Symbol]],TickerList!$G3:$G97,TickerList!M3:M97) -> 45895 | Z4: =_xlfn.XLOOKUP(RTData[[#This Row],[Ticker_Symbol]],TickerList!$G3:$G97,TickerList!N3:N97) -> 0 | AA4: =_xlfn.XLOOKUP(RTData[[#This Row],[Ticker_Symbol]],TickerList!$G3:$G97,TickerList!O3:O97) -> 0.0117 | AB4: 0.0001 | AC4: 0.003 | AD4: 15.33 | AE4: =_xlfn.LET(_xlpm.New1YT,RTData[[#This Row],[1YT]], _xlpm.Old1YT,IF(ISNUMBER(RTData[[#This Row],[Old1YT]]),RTData[[#This Row],[Old1YT]],VALUE(LEFT(RTData[[#This Row],[Old1YT]],FIND("/",RTData[[#This Row],[Old1YT]],1)-1))), IF(OR(RTData[[#This Row],[1YT]]=0,_xlpm.Old1YT=0),0,(_xlpm.New1YT-_xlpm.Old1YT)/_xlpm.Old1YT)) -> 0.34811937 | AF4: =TEXT(RTData[[#This Row],[1YT]],"#,#0.00")&" < "&RTData[[#This Row],[Old1YT]] -> 20.67 < 15.33
A5: {=_xlfn.SINGLE(RTData[suffix])&_FV(RTData[[#This Row],[Company Name]],"Ticker symbol",TRUE)} -> AET | B5: =D101/100 -> 0.011358473 | C5: #VALUE! | D5: {=_FV(RTData[[#This Row],[Company Name]],"Currency")} -> GBp | E5: {=_FV(RTData[[#This Row],[Company Name]],"Last trade time",TRUE)} -> 45966.691 | F5: {=_FV(RTData[[#This Row],[Company Name]],"Previous close",TRUE)} -> 45 | G5: {=_FV(RTData[[#This Row],[Company Name]],"Open")} -> 44.3 | H5: {=_FV(RTData[[#This Row],[Company Name]],"Price")} -> 46 | I5: {=_FV(RTData[[#This Row],[Company Name]],"Low")} -> 44.3 | J5: {=_FV(RTData[[#This Row],[Company Name]],"High")} -> 46 | K5: {=IFERROR(_FV(RTData[[#This Row],[Company Name]],"P/E",TRUE),99)} -> 3.9931 | L5: {=_FV(RTData[[#This Row],[Company Name]],"Change")} -> 1 | M5: {=_FV(RTData[[#This Row],[Company Name]],"Change (%)",TRUE)} -> 0.022222 | N5: {=_FV(RTData[[#This Row],[Company Name]],"52 week low",TRUE)} -> 33.065 | O5: {=_FV(RTData[[#This Row],[Company Name]],"52 week high",TRUE)} -> 56.2 | P5: {=_FV(RTData[[#This Row],[Company Name]],"Volume")} -> 93063 | Q5: {=_FV(RTData[[#This Row],[Company Name]],"Volume average",TRUE)} -> 418370 | R5: {=_FV(RTData[[#This Row],[Company Name]],"Beta")} -> 1.6406 | T5: V | U5: {=_FV(RTData[[#This Row],[Company Name]],"Exchange abbreviation",TRUE)} -> XLON | V5: =IFERROR(RTData[[#This Row],[Volume]]/RTData[[#This Row],[Volume average]],1) -> 0.22244186 | X5: =_xlfn.XLOOKUP(RTData[[#This Row],[Ticker_Symbol]],TickerList!$G4:$G98,TickerList!L4:L98) -> 96.66 | Y5: =_xlfn.XLOOKUP(RTData[[#This Row],[Ticker_Symbol]],TickerList!$G4:$G98,TickerList!M4:M98) -> 0 | Z5: =_xlfn.XLOOKUP(RTData[[#This Row],[Ticker_Symbol]],TickerList!$G4:$G98,TickerList!N4:N98) -> 0 | AA5: =_xlfn.XLOOKUP(RTData[[#This Row],[Ticker_Symbol]],TickerList!$G4:$G98,TickerList!O4:O98) -> 0 | AC5: 0.003 | AD5: 91.96/86.78 | AE5: =_xlfn.LET(_xlpm.New1YT,RTData[[#This Row],[1YT]], _xlpm.Old1YT,IF(ISNUMBER(RTData[[#This Row],[Old1YT]]),RTData[[#This Row],[Old1YT]],VALUE(LEFT(RTData[[#This Row],[Old1YT]],FIND("/",RTData[[#This Row],[Old1YT]],1)-1))), IF(OR(RTData[[#This Row],[1YT]]=0,_xlpm.Old1YT=0),0,(_xlpm.New1YT-_xlpm.Old1YT)/_xlpm.Old1YT)) -> 0.051109178 | AF5: =TEXT(RTData[[#This Row],[1YT]],"#,#0.00")&" < "&RTData[[#This Row],[Old1YT]] -> 96.66 < 91.96/86.78
A6: {=_xlfn.SINGLE(RTData[suffix])&_FV(RTData[[#This Row],[Company Name]],"Ticker symbol",TRUE)} -> AMZN | B6: =D99 -> 0.87001914 | C6: #VALUE! | D6: {=_FV(RTData[[#This Row],[Company Name]],"Currency")} -> USD | E6: {=_FV(RTData[[#This Row],[Company Name]],"Last trade time",TRUE)} -> 45967.001 | F6: {=_FV(RTData[[#This Row],[Company Name]],"Previous close",TRUE)} -> 249.32 | G6: {=_FV(RTData[[#This Row],[Company Name]],"Open")} -> 249.03 | H6: {=_FV(RTData[[#This Row],[Company Name]],"Price")} -> 250.2 | I6: {=_FV(RTData[[#This Row],[Company Name]],"Low")} -> 246.16 | J6: {=_FV(RTData[[#This Row],[Company Name]],"High")} -> 251 | K6: {=IFERROR(_FV(RTData[[#This Row],[Company Name]],"P/E",TRUE),99)} -> 35.344 | L6: {=_FV(RTData[[#This Row],[Company Name]],"Change")} -> 0.88 | M6: {=_FV(RTData[[#This Row],[Company Name]],"Change (%)",TRUE)} -> 0.00353 | N6: {=_FV(RTData[[#This Row],[Company Name]],"52 week low",TRUE)} -> 161.38 | O6: {=_FV(RTData[[#This Row],[Company Name]],"52 week high",TRUE)} -> 258.6 | P6: {=_FV(RTData[[#This Row],[Company Name]],"Volume")} -> 40552606 | Q6: {=_FV(RTData[[#This Row],[Company Name]],"Volume average",TRUE)} -> 53776835 | R6: {=_FV(RTData[[#This Row],[Company Name]],"Beta")} -> 1.3597 | T6: V | U6: {=_FV(RTData[[#This Row],[Company Name]],"Exchange abbreviation",TRUE)} -> XNAS | V6: =IFERROR(RTData[[#This Row],[Volume]]/RTData[[#This Row],[Volume average]],1) -> 0.7540906 | X6: =_xlfn.XLOOKUP(RTData[[#This Row],[Ticker_Symbol]],TickerList!$G5:$G99,TickerList!L5:L99) -> 288.4241 | Y6: =_xlfn.XLOOKUP(RTData[[#This Row],[Ticker_Symbol]],TickerList!$G5:$G99,TickerList!M5:M99) -> 0 | Z6: =_xlfn.XLOOKUP(RTData[[#This Row],[Ticker_Symbol]],TickerList!$G5:$G99,TickerList!N5:N99) -> Oct 30, 2025 | AA6: =_xlfn.XLOOKUP(RTData[[#This Row],[Ticker_Symbol]],TickerList!$G5:$G99,TickerList!O5:O99) -> 0 | AB6: 0.0001 | AC6: 0.003 | AD6: 238.96/218.19 | AE6: =_xlfn.LET(_xlpm.New1YT,RTData[[#This Row],[1YT]], _xlpm.Old1YT,IF(ISNUMBER(RTData[[#This Row],[Old1YT]]),RTData[[#This Row],[Old1YT]],VALUE(LEFT(RTData[[#This Row],[Old1YT]],FIND("/",RTData[[#This Row],[Old1YT]],1)-1))), IF(OR(RTData[[#This Row],[1YT]]=0,_xlpm.Old1YT=0),0,(_xlpm.New1YT-_xlpm.Old1YT)/_xlpm.Old1YT)) -> 0.20699741 | AF6: =TEXT(RTData[[#This Row],[1YT]],"#,#0.00")&" < "&RTData[[#This Row],[Old1YT]] -> 288.42 < 238.96/218.19
A7: {=_xlfn.SINGLE(RTData[suffix])&_FV(RTData[[#This Row],[Company Name]],"Ticker symbol",TRUE)} -> ALDNE | B7: 1 | C7: #VALUE! | D7: {=_FV(RTData[[#This Row],[Company Name]],"Currency")} -> EUR | E7: {=_FV(RTData[[#This Row],[Company Name]],"Last trade time",TRUE)} -> 45966.708 | F7: {=_FV(RTData[[#This Row],[Company Name]],"Previous close",TRUE)} -> 0.788 | G7: {=_FV(RTData[[#This Row],[Company Name]],"Open")} -> 0.788 | H7: {=_FV(RTData[[#This Row],[Company Name]],"Price")} -> 0.79 | I7: {=_FV(RTData[[#This Row],[Company Name]],"Low")} -> 0.77 | J7: {=_FV(RTData[[#This Row],[Company Name]],"High")} -> 0.798 | K7: {=IFERROR(_FV(RTData[[#This Row],[Company Name]],"P/E",TRUE),99)} -> 0 | L7: {=_FV(RTData[[#This Row],[Company Name]],"Change")} -> 0.002 | M7: {=_FV(RTData[[#This Row],[Company Name]],"Change (%)",TRUE)} -> 0.002538 | N7: {=_FV(RTData[[#This Row],[Company Name]],"52 week low",TRUE)} -> 0.65 | O7: {=_FV(RTData[[#This Row],[Company Name]],"52 week high",TRUE)} -> 1.53 | P7: {=_FV(RTData[[#This Row],[Company Name]],"Volume")} -> 2729 | Q7: {=_FV(RTData[[#This Row],[Company Name]],"Volume average",TRUE)} -> 6780 | R7: {=_FV(RTData[[#This Row],[Company Name]],"Beta")} -> 0.9588 | T7: V | U7: {=_FV(RTData[[#This Row],[Company Name]],"Exchange abbreviation",TRUE)} -> XPAR | V7: =IFERROR(RTData[[#This Row],[Volume]]/RTData[[#This Row],[Volume average]],1) -> 0.40250737 | X7: =_xlfn.XLOOKUP(RTData[[#This Row],[Ticker_Symbol]],TickerList!$G6:$G100,TickerList!L6:L100) -> 1.53333 | Y7: =_xlfn.XLOOKUP(RTData[[#This Row],[Ticker_Symbol]],TickerList!$G6:$G100,TickerList!M6:M100) -> 0 | Z7: =_xlfn.XLOOKUP(RTData[[#This Row],[Ticker_Symbol]],TickerList!$G6:$G100,TickerList!N6:N100) -> 0 | AA7: =_xlfn.XLOOKUP(RTData[[#This Row],[Ticker_Symbol]],TickerList!$G6:$G100,TickerList!O6:O100) -> 0 | AC7: 0.003 | AD7: 3.87 | AE7: =_xlfn.LET(_xlpm.New1YT,RTData[[#This Row],[1YT]], _xlpm.Old1YT,IF(ISNUMBER(RTData[[#This Row],[Old1YT]]),RTData[[#This Row],[Old1YT]],VALUE(LEFT(RTData[[#This Row],[Old1YT]],FIND("/",RTData[[#This Row],[Old1YT]],1)-1))), IF(OR(RTData[[#This Row],[1YT]]=0,_xlpm.Old1YT=0),0,(_xlpm.New1YT-_xlpm.Old1YT)/_xlpm.Old1YT)) -> -0.6037907 | AF7: =TEXT(RTData[[#This Row],[1YT]],"#,#0.00")&" < "&RTData[[#This Row],[Old1YT]] -> 1.53 < 3.87
A8: {=_xlfn.SINGLE(RTData[suffix])&_FV(RTData[[#This Row],[Company Name]],"Ticker symbol",TRUE)} -> ASML | B8: 1 | C8: #VALUE! | D8: {=_FV(RTData[[#This Row],[Company Name]],"Currency")} -> EUR | E8: {=_FV(RTData[[#This Row],[Company Name]],"Last trade time",TRUE)} -> 45966.708 | F8: {=_FV(RTData[[#This Row],[Company Name]],"Previous close",TRUE)} -> 918 | G8: {=_FV(RTData[[#This Row],[Company Name]],"Open")} -> 882.9 | H8: {=_FV(RTData[[#This Row],[Company Name]],"Price")} -> 906.6 | I8: {=_FV(RTData[[#This Row],[Company Name]],"Low")} -> 878.4 | J8: {=_FV(RTData[[#This Row],[Company Name]],"High")} -> 913.3 | K8: {=IFERROR(_FV(RTData[[#This Row],[Company Name]],"P/E",TRUE),99)} -> 34.8102 | L8: {=_FV(RTData[[#This Row],[Company Name]],"Change")} -> -11.4 | M8: {=_FV(RTData[[#This Row],[Company Name]],"Change (%)",TRUE)} -> -0.012418 | N8: {=_FV(RTData[[#This Row],[Company Name]],"52 week low",TRUE)} -> 508.4 | O8: {=_FV(RTData[[#This Row],[Company Name]],"52 week high",TRUE)} -> 913.3 | P8: {=_FV(RTData[[#This Row],[Company Name]],"Volume")} -> 663558 | Q8: {=_FV(RTData[[#This Row],[Company Name]],"Volume average",TRUE)} -> 547460 | R8: {=_FV(RTData[[#This Row],[Company Name]],"Beta")} -> 2.1158 | T8: V | U8: {=_FV(RTData[[#This Row],[Company Name]],"Exchange abbreviation",TRUE)} -> XAMS | V8: =IFERROR(RTData[[#This Row],[Volume]]/RTData[[#This Row],[Volume average]],1) -> 1.2120666 | X8: =_xlfn.XLOOKUP(RTData[[#This Row],[Ticker_Symbol]],TickerList!$G7:$G101,TickerList!L7:L101) -> 941.90326 | Y8: =_xlfn.XLOOKUP(RTData[[#This Row],[Ticker_Symbol]],TickerList!$G7:$G101,TickerList!M7:M101) -> 45958 | Z8: =_xlfn.XLOOKUP(RTData[[#This Row],[Ticker_Symbol]],TickerList!$G7:$G101,TickerList!N7:N101) -> 0 | AA8: =_xlfn.XLOOKUP(RTData[[#This Row],[Ticker_Symbol]],TickerList!$G7:$G101,TickerList!O7:O101) -> 0.0069999998 | AC8: 0.003 | AD8: 847.58 | AE8: =_xlfn.LET(_xlpm.New1YT,RTData[[#This Row],[1YT]], _xlpm.Old1YT,IF(ISNUMBER(RTData[[#This Row],[Old1YT]]),RTData[[#This Row],[Old1YT]],VALUE(LEFT(RTData[[#This Row],[Old1YT]],FIND("/",RTData[[#This Row],[Old1YT]],1)-1))), IF(OR(RTData[[#This Row],[1YT]]=0,_xlpm.Old1YT=0),0,(_xlpm.New1YT-_xlpm.Old1YT)/_xlpm.Old1YT)) -> 0.11128538 | AF8: =TEXT(RTData[[#This Row],[1YT]],"#,#0.00")&" < "&RTData[[#This Row],[Old1YT]] -> 941.90 < 847.58
A9: {=_xlfn.SINGLE(RTData[suffix])&_FV(RTData[[#This Row],[Company Name]],"Ticker symbol",TRUE)} -> AVGO | B9: 1 | C9: #VALUE! | D9: {=_FV(RTData[[#This Row],[Company Name]],"Currency")} -> USD | E9: {=_FV(RTData[[#This Row],[Company Name]],"Last trade time",TRUE)} -> 45967 | F9: {=_FV(RTData[[#This Row],[Company Name]],"Previous close",TRUE)} -> 351.94 | G9: {=_FV(RTData[[#This Row],[Company Name]],"Open")} -> 350.89 | H9: {=_FV(RTData[[#This Row],[Company Name]],"Price")} -> 358.98 | I9: {=_FV(RTData[[#This Row],[Company Name]],"Low")} -> 350.0913 | J9: {=_FV(RTData[[#This Row],[Company Name]],"High")} -> 364.8699 | K9: {=IFERROR(_FV(RTData[[#This Row],[Company Name]],"P/E",TRUE),99)} -> 90.2184 | L9: {=_FV(RTData[[#This Row],[Company Name]],"Change")} -> 7.04 | M9: {=_FV(RTData[[#This Row],[Company Name]],"Change (%)",TRUE)} -> 0.020003 | N9: {=_FV(RTData[[#This Row],[Company Name]],"52 week low",TRUE)} -> 138.1 | O9: {=_FV(RTData[[#This Row],[Company Name]],"52 week high",TRUE)} -> 386.48 | P9: {=_FV(RTData[[#This Row],[Company Name]],"Volume")} -> 17071547 | Q9: {=_FV(RTData[[#This Row],[Company Name]],"Volume average",TRUE)} -> 21075301 | R9: {=_FV(RTData[[#This Row],[Company Name]],"Beta")} -> 1.2219 | U9: {=_FV(RTData[[#This Row],[Company Name]],"Exchange abbreviation",TRUE)} -> XNAS | V9: =IFERROR(RTData[[#This Row],[Volume]]/RTData[[#This Row],[Volume average]],1) -> 0.81002625 | X9: =_xlfn.XLOOKUP(RTData[[#This Row],[Ticker_Symbol]],TickerList!$G8:$G102,TickerList!L8:L102) -> 392.38165 | Y9: =_xlfn.XLOOKUP(RTData[[#This Row],[Ticker_Symbol]],TickerList!$G8:$G102,TickerList!M8:M102) -> 45922 | Z9: =_xlfn.XLOOKUP(RTData[[#This Row],[Ticker_Symbol]],TickerList!$G8:$G102,TickerList!N8:N102) -> Dec 11, 2025 | AA9: =_xlfn.XLOOKUP(RTData[[#This Row],[Ticker_Symbol]],TickerList!$G8:$G102,TickerList!O8:O102) -> 0.0064 | AC9: 0.003 | AD9: 848.58 | AE9: =_xlfn.LET(_xlpm.New1YT,RTData[[#This Row],[1YT]], _xlpm.Old1YT,IF(ISNUMBER(RTData[[#This Row],[Old1YT]]),RTData[[#This Row],[Old1YT]],VALUE(LEFT(RTData[[#This Row],[Old1YT]],FIND("/",RTData[[#This Row],[Old1YT]],1)-1))), IF(OR(RTData[[#This Row],[1YT]]=0,_xlpm.Old1YT=0),0,(_xlpm.New1YT-_xlpm.Old1YT)/_xlpm.Old1YT)) -> -0.53760205 | AF9: =TEXT(RTData[[#This Row],[1YT]],"#,#0.00")&" < "&RTData[[#This Row],[Old1YT]] -> 392.38 < 848.58
A10: {=_xlfn.SINGLE(RTData[suffix])&_FV(RTData[[#This Row],[Company Name]],"Ticker symbol",TRUE)} -> AZN | B10: 1 | C10: #VALUE! | D10: {=_FV(RTData[[#This Row],[Company Name]],"Currency")} -> USD | E10: {=_FV(RTData[[#This Row],[Company Name]],"Last trade time",TRUE)} -> 45966.99 | F10: {=_FV(RTData[[#This Row],[Company Name]],"Previous close",TRUE)} -> 82.03 | G10: {=_FV(RTData[[#This Row],[Company Name]],"Open")} -> 81.38 | H10: {=_FV(RTData[[#This Row],[Company Name]],"Price")} -> 81.15 | I10: {=_FV(RTData[[#This Row],[Company Name]],"Low")} -> 81.02 | J10: {=_FV(RTData[[#This Row],[Company Name]],"High")} -> 82.09 | K10: {=IFERROR(_FV(RTData[[#This Row],[Company Name]],"P/E",TRUE),99)} -> 30.5523 | L10: {=_FV(RTData[[#This Row],[Company Name]],"Change")} -> -0.88 | M10: {=_FV(RTData[[#This Row],[Company Name]],"Change (%)",TRUE)} -> -0.010728 | N10: {=_FV(RTData[[#This Row],[Company Name]],"52 week low",TRUE)} -> 61.24 | O10: {=_FV(RTData[[#This Row],[Company Name]],"52 week high",TRUE)} -> 86.57 | P10: {=_FV(RTData[[#This Row],[Company Name]],"Volume")} -> 5442643 | Q10: {=_FV(RTData[[#This Row],[Company Name]],"Volume average",TRUE)} -> 5461602 | R10: {=_FV(RTData[[#This Row],[Company Name]],"Beta")} -> 0.3382 | U10: {=_FV(RTData[[#This Row],[Company Name]],"Exchange abbreviation",TRUE)} -> XNAS | V10: =IFERROR(RTData[[#This Row],[Volume]]/RTData[[#This Row],[Volume average]],1) -> 0.99652867 | X10: =_xlfn.XLOOKUP(RTData[[#This Row],[Ticker_Symbol]],TickerList!$G9:$G103,TickerList!L9:L103) -> 93.25273 | Y10: =_xlfn.XLOOKUP(RTData[[#This Row],[Ticker_Symbol]],TickerList!$G9:$G103,TickerList!M9:M103) -> 45877 | Z10: =_xlfn.XLOOKUP(RTData[[#This Row],[Ticker_Symbol]],TickerList!$G9:$G103,TickerList!N9:N103) -> Nov 6, 2025 | AA10: =_xlfn.XLOOKUP(RTData[[#This Row],[Ticker_Symbol]],TickerList!$G9:$G103,TickerList!O9:O103) -> 0.019 | AC10: 0.003 | AD10: 849.58 | AE10: =_xlfn.LET(_xlpm.New1YT,RTData[[#This Row],[1YT]], _xlpm.Old1YT,IF(ISNUMBER(RTData[[#This Row],[Old1YT]]),RTData[[#This Row],[Old1YT]],VALUE(LEFT(RTData[[#This Row],[Old1YT]],FIND("/",RTData[[#This Row],[Old1YT]],1)-1))), IF(OR(RTData[[#This Row],[1YT]]=0,_xlpm.Old1YT=0),0,(_xlpm.New1YT-_xlpm.Old1YT)/_xlpm.Old1YT)) -> -0.89023667 | AF10: =TEXT(RTData[[#This Row],[1YT]],"#,#0.00")&" < "&RTData[[#This Row],[Old1YT]] -> 93.25 < 849.58
A11: {=_xlfn.SINGLE(RTData[suffix])&_FV(RTData[[#This Row],[Company Name]],"Ticker symbol",TRUE)} -> BLDP | B11: =D99 -> 0.87001914 | C11: #VALUE! | D11: {=_FV(RTData[[#This Row],[Company Name]],"Currency")} -> USD | E11: {=_FV(RTData[[#This Row],[Company Name]],"Last trade time",TRUE)} -> 45966.995 | F11: {=_FV(RTData[[#This Row],[Company Name]],"Previous close",TRUE)} -> 3.37 | G11: {=_FV(RTData[[#This Row],[Company Name]],"Open")} -> 3.37 | H11: {=_FV(RTData[[#This Row],[Company Name]],"Price")} -> 3.65 | I11: {=_FV(RTData[[#This Row],[Company Name]],"Low")} -> 3.37 | J11: {=_FV(RTData[[#This Row],[Company Name]],"High")} -> 3.685 | K11: {=IFERROR(_FV(RTData[[#This Row],[Company Name]],"P/E",TRUE),99)} -> 0 | L11: {=_FV(RTData[[#This Row],[Company Name]],"Change")} -> 0.28 | M11: {=_FV(RTData[[#This Row],[Company Name]],"Change (%)",TRUE)} -> 0.083086 | N11: {=_FV(RTData[[#This Row],[Company Name]],"52 week low",TRUE)} -> 1 | O11: {=_FV(RTData[[#This Row],[Company Name]],"52 week high",TRUE)} -> 4.1 | P11: {=_FV(RTData[[#This Row],[Company Name]],"Volume")} -> 6926072 | Q11: {=_FV(RTData[[#This Row],[Company Name]],"Volume average",TRUE)} -> 8884901 | R11: {=_FV(RTData[[#This Row],[Company Name]],"Beta")} -> 1.7143 | T11: V | U11: {=_FV(RTData[[#This Row],[Company Name]],"Exchange abbreviation",TRUE)} -> XNAS | V11: =IFERROR(RTData[[#This Row],[Volume]]/RTData[[#This Row],[Volume average]],1) -> 0.77953283 | X11: =_xlfn.XLOOKUP(RTData[[#This Row],[Ticker_Symbol]],TickerList!$G10:$G104,TickerList!L10:L104) -> 2.75 | Y11: =_xlfn.XLOOKUP(RTData[[#This Row],[Ticker_Symbol]],TickerList!$G10:$G104,TickerList!M10:M104) -> 0 | Z11: =_xlfn.XLOOKUP(RTData[[#This Row],[Ticker_Symbol]],TickerList!$G10:$G104,TickerList!N10:N104) -> Nov 13, 2025 | AA11: =_xlfn.XLOOKUP(RTData[[#This Row],[Ticker_Symbol]],TickerList!$G10:$G104,TickerList!O10:O104) -> 0 | AB11: 0.0001 | AC11: 0.003 | AD11: 90.46 | AE11: =_xlfn.LET(_xlpm.New1YT,RTData[[#This Row],[1YT]], _xlpm.Old1YT,IF(ISNUMBER(RTData[[#This Row],[Old1YT]]),RTData[[#This Row],[Old1YT]],VALUE(LEFT(RTData[[#This Row],[Old1YT]],FIND("/",RTData[[#This Row],[Old1YT]],1)-1))), IF(OR(RTData[[#This Row],[1YT]]=0,_xlpm.Old1YT=0),0,(_xlpm.New1YT-_xlpm.Old1YT)/_xlpm.Old1YT)) -> -0.96959982 | AF11: =TEXT(RTData[[#This Row],[1YT]],"#,#0.00")&" < "&RTData[[#This Row],[Old1YT]] -> 2.75 < 90.46
A12: {=_xlfn.SINGLE(RTData[suffix])&_FV(RTData[[#This Row],[Company Name]],"Ticker symbol",TRUE)} -> BMRA | B12: =D99 -> 0.87001914 | C12: #VALUE! | D12: {=_FV(RTData[[#This Row],[Company Name]],"Currency")} -> USD | E12: {=_FV(RTData[[#This Row],[Company Name]],"Last trade time",TRUE)} -> 45966.93 | F12: {=_FV(RTData[[#This Row],[Company Name]],"Previous close",TRUE)} -> 2.48 | G12: {=_FV(RTData[[#This Row],[Company Name]],"Open")} -> 2.5 | H12: {=_FV(RTData[[#This Row],[Company Name]],"Price")} -> 2.58 | I12: {=_FV(RTData[[#This Row],[Company Name]],"Low")} -> 2.5 | J12: {=_FV(RTData[[#This Row],[Company Name]],"High")} -> 2.65 | K12: {=IFERROR(_FV(RTData[[#This Row],[Company Name]],"P/E",TRUE),99)} -> 0 | L12: {=_FV(RTData[[#This Row],[Company Name]],"Change")} -> 0.1 | M12: {=_FV(RTData[[#This Row],[Company Name]],"Change (%)",TRUE)} -> 0.040323 | N12: {=_FV(RTData[[#This Row],[Company Name]],"52 week low",TRUE)} -> 2.08 | O12: {=_FV(RTData[[#This Row],[Company Name]],"52 week high",TRUE)} -> 10.16 | P12: {=_FV(RTData[[#This Row],[Company Name]],"Volume")} -> 16669 | Q12: {=_FV(RTData[[#This Row],[Company Name]],"Volume average",TRUE)} -> 204947 | R12: {=_FV(RTData[[#This Row],[Company Name]],"Beta")} -> 0.0622 | T12: V | U12: {=_FV(RTData[[#This Row],[Company Name]],"Exchange abbreviation",TRUE)} -> XNAS | V12: =IFERROR(RTData[[#This Row],[Volume]]/RTData[[#This Row],[Volume average]],1) -> 0.081333223 | X12: =_xlfn.XLOOKUP(RTData[[#This Row],[Ticker_Symbol]],TickerList!$G11:$G105,TickerList!L11:L105) -> 0 | Y12: =_xlfn.XLOOKUP(RTData[[#This Row],[Ticker_Symbol]],TickerList!$G11:$G105,TickerList!M11:M105) -> 0 | Z12: =_xlfn.XLOOKUP(RTData[[#This Row],[Ticker_Symbol]],TickerList!$G11:$G105,TickerList!N11:N105) -> 0 | AA12: =_xlfn.XLOOKUP(RTData[[#This Row],[Ticker_Symbol]],TickerList!$G11:$G105,TickerList!O11:O105) -> 0 | AB12: 0.0001 | AC12: 0.003 | AD12: 2.73 | AE12: =_xlfn.LET(_xlpm.New1YT,RTData[[#This Row],[1YT]], _xlpm.Old1YT,IF(ISNUMBER(RTData[[#This Row],[Old1YT]]),RTData[[#This Row],[Old1YT]],VALUE(LEFT(RTData[[#This Row],[Old1YT]],FIND("/",RTData[[#This Row],[Old1YT]],1)-1))), IF(OR(RTData[[#This Row],[1YT]]=0,_xlpm.Old1YT=0),0,(_xlpm.New1YT-_xlpm.Old1YT)/_xlpm.Old1YT)) -> 0 | AF12: =TEXT(RTData[[#This Row],[1YT]],"#,#0.00")&" < "&RTData[[#This Row],[Old1YT]] -> 0.00 < 2.73
A13: {=_xlfn.SINGLE(RTData[suffix])&_FV(RTData[[#This Row],[Company Name]],"Ticker symbol",TRUE)} -> C | B13: =D99 -> 0.87001914 | C13: #VALUE! | D13: {=_FV(RTData[[#This Row],[Company Name]],"Currency")} -> USD | E13: {=_FV(RTData[[#This Row],[Company Name]],"Last trade time",TRUE)} -> 45966.999 | F13: {=_FV(RTData[[#This Row],[Company Name]],"Previous close",TRUE)} -> 101.01 | G13: {=_FV(RTData[[#This Row],[Company Name]],"Open")} -> 101.25 | H13: {=_FV(RTData[[#This Row],[Company Name]],"Price")} -> 101.72 | I13: {=_FV(RTData[[#This Row],[Company Name]],"Low")} -> 99.012 | J13: {=_FV(RTData[[#This Row],[Company Name]],"High")} -> 102.275 | K13: {=IFERROR(_FV(RTData[[#This Row],[Company Name]],"P/E",TRUE),99)} -> 14.2994 | L13: {=_FV(RTData[[#This Row],[Company Name]],"Change")} -> 0.71 | M13: {=_FV(RTData[[#This Row],[Company Name]],"Change (%)",TRUE)} -> 0.007029 | N13: {=_FV(RTData[[#This Row],[Company Name]],"52 week low",TRUE)} -> 55.51 | O13: {=_FV(RTData[[#This Row],[Company Name]],"52 week high",TRUE)} -> 105.59 | P13: {=_FV(RTData[[#This Row],[Company Name]],"Volume")} -> 9990774 | Q13: {=_FV(RTData[[#This Row],[Company Name]],"Volume average",TRUE)} -> 13407839 | R13: {=_FV(RTData[[#This Row],[Company Name]],"Beta")} -> 1.1959 | T13: V | U13: {=_FV(RTData[[#This Row],[Company Name]],"Exchange abbreviation",TRUE)} -> XNYS | V13: =IFERROR(RTData[[#This Row],[Volume]]/RTData[[#This Row],[Volume average]],1) -> 0.74514424 | X13: =_xlfn.XLOOKUP(RTData[[#This Row],[Ticker_Symbol]],TickerList!$G12:$G106,TickerList!L12:L106) -> 113.7619 | Y13: =_xlfn.XLOOKUP(RTData[[#This Row],[Ticker_Symbol]],TickerList!$G12:$G106,TickerList!M12:M106) -> 45964 | Z13: =_xlfn.XLOOKUP(RTData[[#This Row],[Ticker_Symbol]],TickerList!$G12:$G106,TickerList!N12:N106) -> Jan 14, 2026 | AA13: =_xlfn.XLOOKUP(RTData[[#This Row],[Ticker_Symbol]],TickerList!$G12:$G106,TickerList!O12:O106) -> 0.023699999 | AB13: 0.0001 | AC13: 0.003 | AD13: 13.26 | AE13: =_xlfn.LET(_xlpm.New1YT,RTData[[#This Row],[1YT]], _xlpm.Old1YT,IF(ISNUMBER(RTData[[#This Row],[Old1YT]]),RTData[[#This Row],[Old1YT]],VALUE(LEFT(RTData[[#This Row],[Old1YT]],FIND("/",RTData[[#This Row],[Old1YT]],1)-1))), IF(OR(RTData[[#This Row],[1YT]]=0,_xlpm.Old1YT=0),0,(_xlpm.New1YT-_xlpm.Old1YT)/_xlpm.Old1YT)) -> 7.5793288 | AF13: =TEXT(RTData[[#This Row],[1YT]],"#,#0.00")&" < "&RTData[[#This Row],[Old1YT]] -> 113.76 < 13.26
A14: {=_xlfn.SINGLE(RTData[suffix])&_FV(RTData[[#This Row],[Company Name]],"Ticker symbol",TRUE)} -> CSCO | B14: =D99 -> 0.87001914 | C14: #VALUE! | D14: {=_FV(RTData[[#This Row],[Company Name]],"Currency")} -> USD | E14: {=_FV(RTData[[#This Row],[Company Name]],"Last trade time",TRUE)} -> 45966.997 | F14: {=_FV(RTData[[#This Row],[Company Name]],"Previous close",TRUE)} -> 72.32 | G14: {=_FV(RTData[[#This Row],[Company Name]],"Open")} -> 72.22 | H14: {=_FV(RTData[[#This Row],[Company Name]],"Price")} -> 72.1 | I14: {=_FV(RTData[[#This Row],[Company Name]],"Low")} -> 71.34 | J14: {=_FV(RTData[[#This Row],[Company Name]],"High")} -> 72.58 | K14: {=IFERROR(_FV(RTData[[#This Row],[Company Name]],"P/E",TRUE),99)} -> 30.4798 | L14: {=_FV(RTData[[#This Row],[Company Name]],"Change")} -> -0.22 | M14: {=_FV(RTData[[#This Row],[Company Name]],"Change (%)",TRUE)} -> -0.003042 | N14: {=_FV(RTData[[#This Row],[Company Name]],"52 week low",TRUE)} -> 52.11 | O14: {=_FV(RTData[[#This Row],[Company Name]],"52 week high",TRUE)} -> 74.838 | P14: {=_FV(RTData[[#This Row],[Company Name]],"Volume")} -> 16110965 | Q14: {=_FV(RTData[[#This Row],[Company Name]],"Volume average",TRUE)} -> 17757580 | R14: {=_FV(RTData[[#This Row],[Company Name]],"Beta")} -> 0.869 | T14: V | U14: {=_FV(RTData[[#This Row],[Company Name]],"Exchange abbreviation",TRUE)} -> XNAS | V14: =IFERROR(RTData[[#This Row],[Volume]]/RTData[[#This Row],[Volume average]],1) -> 0.90727256 | X14: =_xlfn.XLOOKUP(RTData[[#This Row],[Ticker_Symbol]],TickerList!$G13:$G107,TickerList!L13:L107) -> 76.29095 | Y14: =_xlfn.XLOOKUP(RTData[[#This Row],[Ticker_Symbol]],TickerList!$G13:$G107,TickerList!M13:M107) -> 45933 | Z14: =_xlfn.XLOOKUP(RTData[[#This Row],[Ticker_Symbol]],TickerList!$G13:$G107,TickerList!N13:N107) -> Nov 12, 2025 | AA14: =_xlfn.XLOOKUP(RTData[[#This Row],[Ticker_Symbol]],TickerList!$G13:$G107,TickerList!O13:O107) -> 0.0224 | AB14: 0.0001 | AC14: 0.003 | AD14: 87.38/72.32 | AE14: =_xlfn.LET(_xlpm.New1YT,RTData[[#This Row],[1YT]], _xlpm.Old1YT,IF(ISNUMBER(RTData[[#This Row],[Old1YT]]),RTData[[#This Row],[Old1YT]],VALUE(LEFT(RTData[[#This Row],[Old1YT]],FIND("/",RTData[[#This Row],[Old1YT]],1)-1))), IF(OR(RTData[[#This Row],[1YT]]=0,_xlpm.Old1YT=0),0,(_xlpm.New1YT-_xlpm.Old1YT)/_xlpm.Old1YT)) -> -0.12690604 | AF14: =TEXT(RTData[[#This Row],[1YT]],"#,#0.00")&" < "&RTData[[#This Row],[Old1YT]] -> 76.29 < 87.38/72.32
A15: {=_xlfn.SINGLE(RTData[suffix])&_FV(RTData[[#This Row],[Company Name]],"Ticker symbol",TRUE)} -> CVS | B15: =D99 -> 0.87001914 | C15: #VALUE! | D15: {=_FV(RTData[[#This Row],[Company Name]],"Currency")} -> USD | E15: {=_FV(RTData[[#This Row],[Company Name]],"Last trade time",TRUE)} -> 45966.996 | F15: {=_FV(RTData[[#This Row],[Company Name]],"Previous close",TRUE)} -> 78.08 | G15: {=_FV(RTData[[#This Row],[Company Name]],"Open")} -> 77.99 | H15: {=_FV(RTData[[#This Row],[Company Name]],"Price")} -> 78.56 | I15: {=_FV(RTData[[#This Row],[Company Name]],"Low")} -> 77.89 | J15: {=_FV(RTData[[#This Row],[Company Name]],"High")} -> 79.26 | K15: {=IFERROR(_FV(RTData[[#This Row],[Company Name]],"P/E",TRUE),99)} -> 205.8161 | L15: {=_FV(RTData[[#This Row],[Company Name]],"Change")} -> 0.48 | M15: {=_FV(RTData[[#This Row],[Company Name]],"Change (%)",TRUE)} -> 0.006148 | N15: {=_FV(RTData[[#This Row],[Company Name]],"52 week low",TRUE)} -> 43.56 | O15: {=_FV(RTData[[#This Row],[Company Name]],"52 week high",TRUE)} -> 85.15 | P15: {=_FV(RTData[[#This Row],[Company Name]],"Volume")} -> 6078942 | Q15: {=_FV(RTData[[#This Row],[Company Name]],"Volume average",TRUE)} -> 8003629 | R15: {=_FV(RTData[[#This Row],[Company Name]],"Beta")} -> 0.4818 | T15: V | U15: {=_FV(RTData[[#This Row],[Company Name]],"Exchange abbreviation",TRUE)} -> XNYS | V15: =IFERROR(RTData[[#This Row],[Volume]]/RTData[[#This Row],[Volume average]],1) -> 0.75952321 | X15: =_xlfn.XLOOKUP(RTData[[#This Row],[Ticker_Symbol]],TickerList!$G14:$G108,TickerList!L14:L108) -> 90.48 | Y15: =_xlfn.XLOOKUP(RTData[[#This Row],[Ticker_Symbol]],TickerList!$G14:$G108,TickerList!M14:M108) -> 45953 | Z15: =_xlfn.XLOOKUP(RTData[[#This Row],[Ticker_Symbol]],TickerList!$G14:$G108,TickerList!N14:N108) -> Oct 29, 2025 | AA15: =_xlfn.XLOOKUP(RTData[[#This Row],[Ticker_Symbol]],TickerList!$G14:$G108,TickerList!O14:O108) -> 0.034 | AB15: 0.0001 | AC15: 0.003 | AD15: 75.81476/55.04 | AE15: =_xlfn.LET(_xlpm.New1YT,RTData[[#This Row],[1YT]], _xlpm.Old1YT,IF(ISNUMBER(RTData[[#This Row],[Old1YT]]),RTData[[#This Row],[Old1YT]],VALUE(LEFT(RTData[[#This Row],[Old1YT]],FIND("/",RTData[[#This Row],[Old1YT]],1)-1))), IF(OR(RTData[[#This Row],[1YT]]=0,_xlpm.Old1YT=0),0,(_xlpm.New1YT-_xlpm.Old1YT)/_xlpm.Old1YT)) -> 0.19343516 | AF15: =TEXT(RTData[[#This Row],[1YT]],"#,#0.00")&" < "&RTData[[#This Row],[Old1YT]] -> 90.48 < 75.81476/55.04
A16: {=_xlfn.SINGLE(RTData[suffix])&_FV(RTData[[#This Row],[Company Name]],"Ticker symbol",TRUE)} -> DDD | B16: =D99 -> 0.87001914 | C16: #VALUE! | D16: {=_FV(RTData[[#This Row],[Company Name]],"Currency")} -> USD | E16: {=_FV(RTData[[#This Row],[Company Name]],"Last trade time",TRUE)} -> 45966.987 | F16: {=_FV(RTData[[#This Row],[Company Name]],"Previous close",TRUE)} -> 2.62 | G16: {=_FV(RTData[[#This Row],[Company Name]],"Open")} -> 2.5 | H16: {=_FV(RTData[[#This Row],[Company Name]],"Price")} -> 2.6 | I16: {=_FV(RTData[[#This Row],[Company Name]],"Low")} -> 2.4 | J16: {=_FV(RTData[[#This Row],[Company Name]],"High")} -> 2.695 | K16: {=IFERROR(_FV(RTData[[#This Row],[Company Name]],"P/E",TRUE),99)} -> 99 | L16: {=_FV(RTData[[#This Row],[Company Name]],"Change")} -> -0.02 | M16: {=_FV(RTData[[#This Row],[Company Name]],"Change (%)",TRUE)} -> -0.007634 | N16: {=_FV(RTData[[#This Row],[Company Name]],"52 week low",TRUE)} -> 1.32 | O16: {=_FV(RTData[[#This Row],[Company Name]],"52 week high",TRUE)} -> 4.9991 | P16: {=_FV(RTData[[#This Row],[Company Name]],"Volume")} -> 5452199 | Q16: {=_FV(RTData[[#This Row],[Company Name]],"Volume average",TRUE)} -> 4450047 | R16: {=_FV(RTData[[#This Row],[Company Name]],"Beta")} -> 1.8776 | T16: V | U16: {=_FV(RTData[[#This Row],[Company Name]],"Exchange abbreviation",TRUE)} -> XNYS | V16: =IFERROR(RTData[[#This Row],[Volume]]/RTData[[#This Row],[Volume average]],1) -> 1.2252003 | X16: =_xlfn.XLOOKUP(RTData[[#This Row],[Ticker_Symbol]],TickerList!$G15:$G109,TickerList!L15:L109) -> 3.25 | Y16: =_xlfn.XLOOKUP(RTData[[#This Row],[Ticker_Symbol]],TickerList!$G15:$G109,TickerList!M15:M109) -> 0 | Z16: =_xlfn.XLOOKUP(RTData[[#This Row],[Ticker_Symbol]],TickerList!$G15:$G109,TickerList!N15:N109) -> Nov 4, 2025 | AA16: =_xlfn.XLOOKUP(RTData[[#This Row],[Ticker_Symbol]],TickerList!$G15:$G109,TickerList!O15:O109) -> 0 | AB16: 0.0001 | AC16: 0.003 | AD16: 72.3 | AE16: =_xlfn.LET(_xlpm.New1YT,RTData[[#This Row],[1YT]], _xlpm.Old1YT,IF(ISNUMBER(RTData[[#This Row],[Old1YT]]),RTData[[#This Row],[Old1YT]],VALUE(LEFT(RTData[[#This Row],[Old1YT]],FIND("/",RTData[[#This Row],[Old1YT]],1)-1))), IF(OR(RTData[[#This Row],[1YT]]=0,_xlpm.Old1YT=0),0,(_xlpm.New1YT-_xlpm.Old1YT)/_xlpm.Old1YT)) -> -0.95504841 | AF16: =TEXT(RTData[[#This Row],[1YT]],"#,#0.00")&" < "&RTData[[#This Row],[Old1YT]] -> 3.25 < 72.3
A17: {=_xlfn.SINGLE(RTData[suffix])&_FV(RTData[[#This Row],[Company Name]],"Ticker symbol",TRUE)} -> DIS | B17: =D99 -> 0.87001914 | C17: #VALUE! | D17: {=_FV(RTData[[#This Row],[Company Name]],"Currency")} -> USD | E17: {=_FV(RTData[[#This Row],[Company Name]],"Last trade time",TRUE)} -> 45966.997 | F17: {=_FV(RTData[[#This Row],[Company Name]],"Previous close",TRUE)} -> 111.47 | G17: {=_FV(RTData[[#This Row],[Company Name]],"Open")} -> 111.35 | H17: {=_FV(RTData[[#This Row],[Company Name]],"Price")} -> 111.34 | I17: {=_FV(RTData[[#This Row],[Company Name]],"Low")} -> 110.6 | J17: {=_FV(RTData[[#This Row],[Company Name]],"High")} -> 111.97 | K17: {=IFERROR(_FV(RTData[[#This Row],[Company Name]],"P/E",TRUE),99)} -> 17.4558 | L17: {=_FV(RTData[[#This Row],[Company Name]],"Change")} -> -0.13 | M17: {=_FV(RTData[[#This Row],[Company Name]],"Change (%)",TRUE)} -> -0.001166 | N17: {=_FV(RTData[[#This Row],[Company Name]],"52 week low",TRUE)} -> 80.1 | O17: {=_FV(RTData[[#This Row],[Company Name]],"52 week high",TRUE)} -> 124.69 | P17: {=_FV(RTData[[#This Row],[Company Name]],"Volume")} -> 5745085 | Q17: {=_FV(RTData[[#This Row],[Company Name]],"Volume average",TRUE)} -> 7629637 | R17: {=_FV(RTData[[#This Row],[Company Name]],"Beta")} -> 1.4864 | T17: V | U17: {=_FV(RTData[[#This Row],[Company Name]],"Exchange abbreviation",TRUE)} -> XNYS | V17: =IFERROR(RTData[[#This Row],[Volume]]/RTData[[#This Row],[Volume average]],1) -> 0.75299585 | X17: =_xlfn.XLOOKUP(RTData[[#This Row],[Ticker_Symbol]],TickerList!$G16:$G110,TickerList!L16:L110) -> 134.0724 | Y17: =_xlfn.XLOOKUP(RTData[[#This Row],[Ticker_Symbol]],TickerList!$G16:$G110,TickerList!M16:M110) -> 45832 | Z17: =_xlfn.XLOOKUP(RTData[[#This Row],[Ticker_Symbol]],TickerList!$G16:$G110,TickerList!N16:N110) -> Nov 13, 2025 | AA17: =_xlfn.XLOOKUP(RTData[[#This Row],[Ticker_Symbol]],TickerList!$G16:$G110,TickerList!O16:O110) -> 0.0089 | AB17: 0.0001 | AC17: 0.003 | AD17: 3.94 | AE17: =_xlfn.LET(_xlpm.New1YT,RTData[[#This Row],[1YT]], _xlpm.Old1YT,IF(ISNUMBER(RTData[[#This Row],[Old1YT]]),RTData[[#This Row],[Old1YT]],VALUE(LEFT(RTData[[#This Row],[Old1YT]],FIND("/",RTData[[#This Row],[Old1YT]],1)-1))), IF(OR(RTData[[#This Row],[1YT]]=0,_xlpm.Old1YT=0),0,(_xlpm.New1YT-_xlpm.Old1YT)/_xlpm.Old1YT)) -> 33.028528 | AF17: =TEXT(RTData[[#This Row],[1YT]],"#,#0.00")&" < "&RTData[[#This Row],[Old1YT]] -> 134.07 < 3.94
A18: {=_xlfn.SINGLE(RTData[suffix])&_FV(RTData[[#This Row],[Company Name]],"Ticker symbol",TRUE)} -> DSY | B18: =D99 -> 0.87001914 | C18: #VALUE! | D18: {=_FV(RTData[[#This Row],[Company Name]],"Currency")} -> EUR | E18: {=_FV(RTData[[#This Row],[Company Name]],"Last trade time",TRUE)} -> 45966.708 | F18: {=_FV(RTData[[#This Row],[Company Name]],"Previous close",TRUE)} -> 24.04 | G18: {=_FV(RTData[[#This Row],[Company Name]],"Open")} -> 23.86 | H18: {=_FV(RTData[[#This Row],[Company Name]],"Price")} -> 23.98 | I18: {=_FV(RTData[[#This Row],[Company Name]],"Low")} -> 23.75 | J18: {=_FV(RTData[[#This Row],[Company Name]],"High")} -> 24.12 | K18: {=IFERROR(_FV(RTData[[#This Row],[Company Name]],"P/E",TRUE),99)} -> 26.7933 | L18: {=_FV(RTData[[#This Row],[Company Name]],"Change")} -> -0.06 | M18: {=_FV(RTData[[#This Row],[Company Name]],"Change (%)",TRUE)} -> -0.002496 | N18: {=_FV(RTData[[#This Row],[Company Name]],"52 week low",TRUE)} -> 23.75 | O18: {=_FV(RTData[[#This Row],[Company Name]],"52 week high",TRUE)} -> 41.17 | P18: {=_FV(RTData[[#This Row],[Company Name]],"Volume")} -> 1361709 | Q18: {=_FV(RTData[[#This Row],[Company Name]],"Volume average",TRUE)} -> 2619000 | R18: {=_FV(RTData[[#This Row],[Company Name]],"Beta")} -> 0.7891 | T18: V | U18: {=_FV(RTData[[#This Row],[Company Name]],"Exchange abbreviation",TRUE)} -> XPAR | V18: =IFERROR(RTData[[#This Row],[Volume]]/RTData[[#This Row],[Volume average]],1) -> 0.51993471 | X18: =_xlfn.XLOOKUP(RTData[[#This Row],[Ticker_Symbol]],TickerList!$G17:$G111,TickerList!L17:L111) -> 31.87778 | Y18: =_xlfn.XLOOKUP(RTData[[#This Row],[Ticker_Symbol]],TickerList!$G17:$G111,TickerList!M17:M111) -> 45803 | Z18: =_xlfn.XLOOKUP(RTData[[#This Row],[Ticker_Symbol]],TickerList!$G17:$G111,TickerList!N17:N111) -> 0 | AA18: =_xlfn.XLOOKUP(RTData[[#This Row],[Ticker_Symbol]],TickerList!$G17:$G111,TickerList!O17:O111) -> 0.0106 | AB18: 0.0001 | AC18: 0.003 | AD18: 111.22 | AE18: =_xlfn.LET(_xlpm.New1YT,RTData[[#This Row],[1YT]], _xlpm.Old1YT,IF(ISNUMBER(RTData[[#This Row],[Old1YT]]),RTData[[#This Row],[Old1YT]],VALUE(LEFT(RTData[[#This Row],[Old1YT]],FIND("/",RTData[[#This Row],[Old1YT]],1)-1))), IF(OR(RTData[[#This Row],[1YT]]=0,_xlpm.Old1YT=0),0,(_xlpm.New1YT-_xlpm.Old1YT)/_xlpm.Old1YT)) -> -0.71338087 | AF18: =TEXT(RTData[[#This Row],[1YT]],"#,#0.00")&" < "&RTData[[#This Row],[Old1YT]] -> 31.88 < 111.22
A19: {=_xlfn.SINGLE(RTData[suffix])&_FV(RTData[[#This Row],[Company Name]],"Ticker symbol",TRUE)} -> DVA | B19: 1 | C19: #VALUE! | D19: {=_FV(RTData[[#This Row],[Company Name]],"Currency")} -> USD | E19: {=_FV(RTData[[#This Row],[Company Name]],"Last trade time",TRUE)} -> 45966.979 | F19: {=_FV(RTData[[#This Row],[Company Name]],"Previous close",TRUE)} -> 119.97 | G19: {=_FV(RTData[[#This Row],[Company Name]],"Open")} -> 119.69 | H19: {=_FV(RTData[[#This Row],[Company Name]],"Price")} -> 121.16 | I19: {=_FV(RTData[[#This Row],[Company Name]],"Low")} -> 119.245 | J19: {=_FV(RTData[[#This Row],[Company Name]],"High")} -> 121.87 | K19: {=IFERROR(_FV(RTData[[#This Row],[Company Name]],"P/E",TRUE),99)} -> 12.4745 | L19: {=_FV(RTData[[#This Row],[Company Name]],"Change")} -> 1.19 | M19: {=_FV(RTData[[#This Row],[Company Name]],"Change (%)",TRUE)} -> 0.009919 | N19: {=_FV(RTData[[#This Row],[Company Name]],"52 week low",TRUE)} -> 115.39 | O19: {=_FV(RTData[[#This Row],[Company Name]],"52 week high",TRUE)} -> 179.6 | P19: {=_FV(RTData[[#This Row],[Company Name]],"Volume")} -> 936632 | Q19: {=_FV(RTData[[#This Row],[Company Name]],"Volume average",TRUE)} -> 818913 | R19: {=_FV(RTData[[#This Row],[Company Name]],"Beta")} -> 0.9898 | T19: V | U19: {=_FV(RTData[[#This Row],[Company Name]],"Exchange abbreviation",TRUE)} -> XNYS | V19: =IFERROR(RTData[[#This Row],[Volume]]/RTData[[#This Row],[Volume average]],1) -> 1.1437503 | X19: =_xlfn.XLOOKUP(RTData[[#This Row],[Ticker_Symbol]],TickerList!$G18:$G112,TickerList!L18:L112) -> 147.125 | Y19: =_xlfn.XLOOKUP(RTData[[#This Row],[Ticker_Symbol]],TickerList!$G18:$G112,TickerList!M18:M112) -> 0 | Z19: =_xlfn.XLOOKUP(RTData[[#This Row],[Ticker_Symbol]],TickerList!$G18:$G112,TickerList!N18:N112) -> Oct 29, 2025 | AA19: =_xlfn.XLOOKUP(RTData[[#This Row],[Ticker_Symbol]],TickerList!$G18:$G112,TickerList!O18:O112) -> 0 | AC19: 0.003 | AD19: 37.97/38.13/38.23 | AE19: =_xlfn.LET(_xlpm.New1YT,RTData[[#This Row],[1YT]], _xlpm.Old1YT,IF(ISNUMBER(RTData[[#This Row],[Old1YT]]),RTData[[#This Row],[Old1YT]],VALUE(LEFT(RTData[[#This Row],[Old1YT]],FIND("/",RTData[[#This Row],[Old1YT]],1)-1))), IF(OR(RTData[[#This Row],[1YT]]=0,_xlpm.Old1YT=0),0,(_xlpm.New1YT-_xlpm.Old1YT)/_xlpm.Old1YT)) -> 2.8747696 | AF19: =TEXT(RTData[[#This Row],[1YT]],"#,#0.00")&" < "&RTData[[#This Row],[Old1YT]] -> 147.13 < 37.97/38.13/38.23
A20: {=_xlfn.SINGLE(RTData[suffix])&_FV(RTData[[#This Row],[Company Name]],"Ticker symbol",TRUE)} -> DXC | B20: =D99 -> 0.87001914 | C20: #VALUE! | D20: {=_FV(RTData[[#This Row],[Company Name]],"Currency")} -> USD | E20: {=_FV(RTData[[#This Row],[Company Name]],"Last trade time",TRUE)} -> 45966.979 | F20: {=_FV(RTData[[#This Row],[Company Name]],"Previous close",TRUE)} -> 13.54 | G20: {=_FV(RTData[[#This Row],[Company Name]],"Open")} -> 13.59 | H20: {=_FV(RTData[[#This Row],[Company Name]],"Price")} -> 13.81 | I20: {=_FV(RTData[[#This Row],[Company Name]],"Low")} -> 13.59 | J20: {=_FV(RTData[[#This Row],[Company Name]],"High")} -> 14.135 | K20: {=IFERROR(_FV(RTData[[#This Row],[Company Name]],"P/E",TRUE),99)} -> 6.7432 | L20: {=_FV(RTData[[#This Row],[Company Name]],"Change")} -> 0.27 | M20: {=_FV(RTData[[#This Row],[Company Name]],"Change (%)",TRUE)} -> 0.019941 | N20: {=_FV(RTData[[#This Row],[Company Name]],"52 week low",TRUE)} -> 12.24 | O20: {=_FV(RTData[[#This Row],[Company Name]],"52 week high",TRUE)} -> 24.83 | P20: {=_FV(RTData[[#This Row],[Company Name]],"Volume")} -> 2522383 | Q20: {=_FV(RTData[[#This Row],[Company Name]],"Volume average",TRUE)} -> 1948566 | R20: {=_FV(RTData[[#This Row],[Company Name]],"Beta")} -> 1.0907 | T20: V | U20: {=_FV(RTData[[#This Row],[Company Name]],"Exchange abbreviation",TRUE)} -> XNYS | V20: =IFERROR(RTData[[#This Row],[Volume]]/RTData[[#This Row],[Volume average]],1) -> 1.2944817 | X20: =_xlfn.XLOOKUP(RTData[[#This Row],[Ticker_Symbol]],TickerList!$G19:$G113,TickerList!L19:L113) -> 14.5 | Y20: =_xlfn.XLOOKUP(RTData[[#This Row],[Ticker_Symbol]],TickerList!$G19:$G113,TickerList!M19:M113) -> 43914 | Z20: =_xlfn.XLOOKUP(RTData[[#This Row],[Ticker_Symbol]],TickerList!$G19:$G113,TickerList!N19:N113) -> Oct 30, 2025 | AA20: =_xlfn.XLOOKUP(RTData[[#This Row],[Ticker_Symbol]],TickerList!$G19:$G113,TickerList!O19:O113) -> 0 | AB20: 0.0001 | AC20: 0.003 | AD20: 157.9 | AE20: =_xlfn.LET(_xlpm.New1YT,RTData[[#This Row],[1YT]], _xlpm.Old1YT,IF(ISNUMBER(RTData[[#This Row],[Old1YT]]),RTData[[#This Row],[Old1YT]],VALUE(LEFT(RTData[[#This Row],[Old1YT]],FIND("/",RTData[[#This Row],[Old1YT]],1)-1))), IF(OR(RTData[[#This Row],[1YT]]=0,_xlpm.Old1YT=0),0,(_xlpm.New1YT-_xlpm.Old1YT)/_xlpm.Old1YT)) -> -0.90816973 | AF20: =TEXT(RTData[[#This Row],[1YT]],"#,#0.00")&" < "&RTData[[#This Row],[Old1YT]] -> 14.50 < 157.9
A21: {=_xlfn.SINGLE(RTData[suffix])&_FV(RTData[[#This Row],[Company Name]],"Ticker symbol",TRUE)} -> EOAN | B21: =D99 -> 0.87001914 | C21: #VALUE! | D21: {=_FV(RTData[[#This Row],[Company Name]],"Currency")} -> EUR | E21: {=_FV(RTData[[#This Row],[Company Name]],"Last trade time",TRUE)} -> 45966.878 | F21: {=_FV(RTData[[#This Row],[Company Name]],"Previous close",TRUE)} -> 15.75 | G21: {=_FV(RTData[[#This Row],[Company Name]],"Open")} -> 15.825 | H21: {=_FV(RTData[[#This Row],[Company Name]],"Price")} -> 16.05 | I21: {=_FV(RTData[[#This Row],[Company Name]],"Low")} -> 15.825 | J21: {=_FV(RTData[[#This Row],[Company Name]],"High")} -> 16.05 | K21: {=IFERROR(_FV(RTData[[#This Row],[Company Name]],"P/E",TRUE),99)} -> 13.2645 | L21: {=_FV(RTData[[#This Row],[Company Name]],"Change")} -> 0.3 | M21: {=_FV(RTData[[#This Row],[Company Name]],"Change (%)",TRUE)} -> 0.019048 | N21: {=_FV(RTData[[#This Row],[Company Name]],"52 week low",TRUE)} -> 7.3 | O21: {=_FV(RTData[[#This Row],[Company Name]],"52 week high",TRUE)} -> 16.515 | P21: {=_FV(RTData[[#This Row],[Company Name]],"Volume")} -> 4253 | Q21: {=_FV(RTData[[#This Row],[Company Name]],"Volume average",TRUE)} -> 2907640 | R21: {=_FV(RTData[[#This Row],[Company Name]],"Beta")} -> 0.8536 | T21: V | U21: {=_FV(RTData[[#This Row],[Company Name]],"Exchange abbreviation",TRUE)} -> XFRA | V21: =IFERROR(RTData[[#This Row],[Volume]]/RTData[[#This Row],[Volume average]],1) -> 0.0014626983 | X21: =_xlfn.XLOOKUP(RTData[[#This Row],[Ticker_Symbol]],TickerList!$G20:$G114,TickerList!L20:L114) -> 16.91959 | Y21: =_xlfn.XLOOKUP(RTData[[#This Row],[Ticker_Symbol]],TickerList!$G20:$G114,TickerList!M20:M114) -> 45793 | Z21: =_xlfn.XLOOKUP(RTData[[#This Row],[Ticker_Symbol]],TickerList!$G20:$G114,TickerList!N20:N114) -> 0 | AA21: =_xlfn.XLOOKUP(RTData[[#This Row],[Ticker_Symbol]],TickerList!$G20:$G114,TickerList!O20:O114) -> 0.0341 | AB21: 0.0001 | AC21: 0.003 | AD21: 19.77 | AE21: =_xlfn.LET(_xlpm.New1YT,RTData[[#This Row],[1YT]], _xlpm.Old1YT,IF(ISNUMBER(RTData[[#This Row],[Old1YT]]),RTData[[#This Row],[Old1YT]],VALUE(LEFT(RTData[[#This Row],[Old1YT]],FIND("/",RTData[[#This Row],[Old1YT]],1)-1))), IF(OR(RTData[[#This Row],[1YT]]=0,_xlpm.Old1YT=0),0,(_xlpm.New1YT-_xlpm.Old1YT)/_xlpm.Old1YT)) -> -0.14417855 | AF21: =TEXT(RTData[[#This Row],[1YT]],"#,#0.00")&" < "&RTData[[#This Row],[Old1YT]] -> 16.92 < 19.77
A22: {=_xlfn.SINGLE(RTData[suffix])&_FV(RTData[[#This Row],[Company Name]],"Ticker symbol",TRUE)} -> EPIX | B22: 1 | C22: #VALUE! | D22: {=_FV(RTData[[#This Row],[Company Name]],"Currency")} -> USD | E22: {=_FV(RTData[[#This Row],[Company Name]],"Last trade time",TRUE)} -> 45938.992 | F22: {=_FV(RTData[[#This Row],[Company Name]],"Previous close",TRUE)} -> 0.205 | G22: {=_FV(RTData[[#This Row],[Company Name]],"Open")} -> 0.2 | H22: {=_FV(RTData[[#This Row],[Company Name]],"Price")} -> 0.2012 | I22: {=_FV(RTData[[#This Row],[Company Name]],"Low")} -> 0.1899 | J22: {=_FV(RTData[[#This Row],[Company Name]],"High")} -> 0.207 | K22: {=IFERROR(_FV(RTData[[#This Row],[Company Name]],"P/E",TRUE),99)} -> 0 | L22: {=_FV(RTData[[#This Row],[Company Name]],"Change")} -> 0 | M22: {=_FV(RTData[[#This Row],[Company Name]],"Change (%)",TRUE)} -> 0 | N22: {=_FV(RTData[[#This Row],[Company Name]],"52 week low",TRUE)} -> 0.1733 | O22: {=_FV(RTData[[#This Row],[Company Name]],"52 week high",TRUE)} -> 0.825 | P22: {=_FV(RTData[[#This Row],[Company Name]],"Volume")} -> 5945141 | Q22: {=_FV(RTData[[#This Row],[Company Name]],"Volume average",TRUE)} -> 3209641 | R22: {=_FV(RTData[[#This Row],[Company Name]],"Beta")} -> 1.5514 | T22: V | U22: {=_FV(RTData[[#This Row],[Company Name]],"Exchange abbreviation",TRUE)} -> XNAS | V22: =IFERROR(RTData[[#This Row],[Volume]]/RTData[[#This Row],[Volume average]],1) -> 1.852276 | X22: =_xlfn.XLOOKUP(RTData[[#This Row],[Ticker_Symbol]],TickerList!$G21:$G115,TickerList!L21:L115) -> 0 | Y22: =_xlfn.XLOOKUP(RTData[[#This Row],[Ticker_Symbol]],TickerList!$G21:$G115,TickerList!M21:M115) -> 45894 | Z22: =_xlfn.XLOOKUP(RTData[[#This Row],[Ticker_Symbol]],TickerList!$G21:$G115,TickerList!N21:N115) -> 0 | AA22: =_xlfn.XLOOKUP(RTData[[#This Row],[Ticker_Symbol]],TickerList!$G21:$G115,TickerList!O21:O115) -> 0 | AC22: 0.003 | AD22: 16.71/16.47/14.8 | AE22: =_xlfn.LET(_xlpm.New1YT,RTData[[#This Row],[1YT]], _xlpm.Old1YT,IF(ISNUMBER(RTData[[#This Row],[Old1YT]]),RTData[[#This Row],[Old1YT]],VALUE(LEFT(RTData[[#This Row],[Old1YT]],FIND("/",RTData[[#This Row],[Old1YT]],1)-1))), IF(OR(RTData[[#This Row],[1YT]]=0,_xlpm.Old1YT=0),0,(_xlpm.New1YT-_xlpm.Old1YT)/_xlpm.Old1YT)) -> 0 | AF22: =TEXT(RTData[[#This Row],[1YT]],"#,#0.00")&" < "&RTData[[#This Row],[Old1YT]] -> 0.00 < 16.71/16.47/14.8
A23: {=_xlfn.SINGLE(RTData[suffix])&_FV(RTData[[#This Row],[Company Name]],"Ticker symbol",TRUE)} -> GM | B23: =D99 -> 0.87001914 | C23: #VALUE! | D23: {=_FV(RTData[[#This Row],[Company Name]],"Currency")} -> USD | E23: {=_FV(RTData[[#This Row],[Company Name]],"Last trade time",TRUE)} -> 45966.998 | F23: {=_FV(RTData[[#This Row],[Company Name]],"Previous close",TRUE)} -> 66.87 | G23: {=_FV(RTData[[#This Row],[Company Name]],"Open")} -> 67.04 | H23: {=_FV(RTData[[#This Row],[Company Name]],"Price")} -> 68.78 | I23: {=_FV(RTData[[#This Row],[Company Name]],"Low")} -> 67.04 | J23: {=_FV(RTData[[#This Row],[Company Name]],"High")} -> 69.26 | K23: {=IFERROR(_FV(RTData[[#This Row],[Company Name]],"P/E",TRUE),99)} -> 13.229 | L23: {=_FV(RTData[[#This Row],[Company Name]],"Change")} -> 1.91 | M23: {=_FV(RTData[[#This Row],[Company Name]],"Change (%)",TRUE)} -> 0.028563 | N23: {=_FV(RTData[[#This Row],[Company Name]],"52 week low",TRUE)} -> 41.6 | O23: {=_FV(RTData[[#This Row],[Company Name]],"52 week high",TRUE)} -> 70.24 | P23: {=_FV(RTData[[#This Row],[Company Name]],"Volume")} -> 7806815 | Q23: {=_FV(RTData[[#This Row],[Company Name]],"Volume average",TRUE)} -> 10651288 | R23: {=_FV(RTData[[#This Row],[Company Name]],"Beta")} -> 1.314 | T23: V | U23: {=_FV(RTData[[#This Row],[Company Name]],"Exchange abbreviation",TRUE)} -> XNYS | V23: =IFERROR(RTData[[#This Row],[Volume]]/RTData[[#This Row],[Volume average]],1) -> 0.73294563 | X23: =_xlfn.XLOOKUP(RTData[[#This Row],[Ticker_Symbol]],TickerList!$G22:$G116,TickerList!L22:L116) -> 73.15385 | Y23: =_xlfn.XLOOKUP(RTData[[#This Row],[Ticker_Symbol]],TickerList!$G22:$G116,TickerList!M22:M116) -> 45996 | Z23: =_xlfn.XLOOKUP(RTData[[#This Row],[Ticker_Symbol]],TickerList!$G22:$G116,TickerList!N22:N116) -> Oct 21, 2025 | AA23: =_xlfn.XLOOKUP(RTData[[#This Row],[Ticker_Symbol]],TickerList!$G22:$G116,TickerList!O22:O116) -> 0.0087 | AB23: 0.0001 | AC23: 0.003 | AD23: 9.32 | AE23: =_xlfn.LET(_xlpm.New1YT,RTData[[#This Row],[1YT]], _xlpm.Old1YT,IF(ISNUMBER(RTData[[#This Row],[Old1YT]]),RTData[[#This Row],[Old1YT]],VALUE(LEFT(RTData[[#This Row],[Old1YT]],FIND("/",RTData[[#This Row],[Old1YT]],1)-1))), IF(OR(RTData[[#This Row],[1YT]]=0,_xlpm.Old1YT=0),0,(_xlpm.New1YT-_xlpm.Old1YT)/_xlpm.Old1YT)) -> 6.8491255 | AF23: =TEXT(RTData[[#This Row],[1YT]],"#,#0.00")&" < "&RTData[[#This Row],[Old1YT]] -> 73.15 < 9.32
A24: {=_xlfn.SINGLE(RTData[suffix])&_FV(RTData[[#This Row],[Company Name]],"Ticker symbol",TRUE)} -> HPE | B24: =D99 -> 0.87001914 | C24: #VALUE! | D24: {=_FV(RTData[[#This Row],[Company Name]],"Currency")} -> USD | E24: {=_FV(RTData[[#This Row],[Company Name]],"Last trade time",TRUE)} -> 45966.998 | F24: {=_FV(RTData[[#This Row],[Company Name]],"Previous close",TRUE)} -> 23.56 | G24: {=_FV(RTData[[#This Row],[Company Name]],"Open")} -> 23.6 | H24: {=_FV(RTData[[#This Row],[Company Name]],"Price")} -> 23.7 | I24: {=_FV(RTData[[#This Row],[Company Name]],"Low")} -> 23.39 | J24: {=_FV(RTData[[#This Row],[Company Name]],"High")} -> 24.03 | K24: {=IFERROR(_FV(RTData[[#This Row],[Company Name]],"P/E",TRUE),99)} -> 28.4275 | L24: {=_FV(RTData[[#This Row],[Company Name]],"Change")} -> 0.14 | M24: {=_FV(RTData[[#This Row],[Company Name]],"Change (%)",TRUE)} -> 0.005942 | N24: {=_FV(RTData[[#This Row],[Company Name]],"52 week low",TRUE)} -> 11.965 | O24: {=_FV(RTData[[#This Row],[Company Name]],"52 week high",TRUE)} -> 26.44 | P24: {=_FV(RTData[[#This Row],[Company Name]],"Volume")} -> 27390755 | Q24: {=_FV(RTData[[#This Row],[Company Name]],"Volume average",TRUE)} -> 37677726 | R24: {=_FV(RTData[[#This Row],[Company Name]],"Beta")} -> 1.3427 | T24: V | U24: {=_FV(RTData[[#This Row],[Company Name]],"Exchange abbreviation",TRUE)} -> XNYS | V24: =IFERROR(RTData[[#This Row],[Volume]]/RTData[[#This Row],[Volume average]],1) -> 0.72697474 | X24: =_xlfn.XLOOKUP(RTData[[#This Row],[Ticker_Symbol]],TickerList!$G23:$G117,TickerList!L23:L117) -> 26.51211 | Y24: =_xlfn.XLOOKUP(RTData[[#This Row],[Ticker_Symbol]],TickerList!$G23:$G117,TickerList!M23:M117) -> 45918 | Z24: =_xlfn.XLOOKUP(RTData[[#This Row],[Ticker_Symbol]],TickerList!$G23:$G117,TickerList!N23:N117) -> Dec 4, 2025 | AA24: =_xlfn.XLOOKUP(RTData[[#This Row],[Ticker_Symbol]],TickerList!$G23:$G117,TickerList!O23:O117) -> 0.021300001 | AB24: 0.0001 | AC24: 0.003 | AD24: 56.25 | AE24: =_xlfn.LET(_xlpm.New1YT,RTData[[#This Row],[1YT]], _xlpm.Old1YT,IF(ISNUMBER(RTData[[#This Row],[Old1YT]]),RTData[[#This Row],[Old1YT]],VALUE(LEFT(RTData[[#This Row],[Old1YT]],FIND("/",RTData[[#This Row],[Old1YT]],1)-1))), IF(OR(RTData[[#This Row],[1YT]]=0,_xlpm.Old1YT=0),0,(_xlpm.New1YT-_xlpm.Old1YT)/_xlpm.Old1YT)) -> -0.5286736 | AF24: =TEXT(RTData[[#This Row],[1YT]],"#,#0.00")&" < "&RTData[[#This Row],[Old1YT]] -> 26.51 < 56.25
A25: {=_xlfn.SINGLE(RTData[suffix])&_FV(RTData[[#This Row],[Company Name]],"Ticker symbol",TRUE)} -> HPQ | B25: =D99 -> 0.87001914 | C25: #VALUE! | D25: {=_FV(RTData[[#This Row],[Company Name]],"Currency")} -> USD | E25: {=_FV(RTData[[#This Row],[Company Name]],"Last trade time",TRUE)} -> 45966.985 | F25: {=_FV(RTData[[#This Row],[Company Name]],"Previous close",TRUE)} -> 25.94 | G25: {=_FV(RTData[[#This Row],[Company Name]],"Open")} -> 25.94 | H25: {=_FV(RTData[[#This Row],[Company Name]],"Price")} -> 26.64 | I25: {=_FV(RTData[[#This Row],[Company Name]],"Low")} -> 25.76 | J25: {=_FV(RTData[[#This Row],[Company Name]],"High")} -> 26.71 | K25: {=IFERROR(_FV(RTData[[#This Row],[Company Name]],"P/E",TRUE),99)} -> 9.7046 | L25: {=_FV(RTData[[#This Row],[Company Name]],"Change")} -> 0.7 | M25: {=_FV(RTData[[#This Row],[Company Name]],"Change (%)",TRUE)} -> 0.026985 | N25: {=_FV(RTData[[#This Row],[Company Name]],"52 week low",TRUE)} -> 21.21 | O25: {=_FV(RTData[[#This Row],[Company Name]],"52 week high",TRUE)} -> 39.795 | P25: {=_FV(RTData[[#This Row],[Company Name]],"Volume")} -> 12247048 | Q25: {=_FV(RTData[[#This Row],[Company Name]],"Volume average",TRUE)} -> 12451001 | R25: {=_FV(RTData[[#This Row],[Company Name]],"Beta")} -> 1.2287 | T25: V | U25: {=_FV(RTData[[#This Row],[Company Name]],"Exchange abbreviation",TRUE)} -> XNYS | V25: =IFERROR(RTData[[#This Row],[Volume]]/RTData[[#This Row],[Volume average]],1) -> 0.98361955 | X25: =_xlfn.XLOOKUP(RTData[[#This Row],[Ticker_Symbol]],TickerList!$G24:$G118,TickerList!L24:L118) -> 28.2825 | Y25: =_xlfn.XLOOKUP(RTData[[#This Row],[Ticker_Symbol]],TickerList!$G24:$G118,TickerList!M24:M118) -> 45910 | Z25: =_xlfn.XLOOKUP(RTData[[#This Row],[Ticker_Symbol]],TickerList!$G24:$G118,TickerList!N24:N118) -> Nov 25, 2025 | AA25: =_xlfn.XLOOKUP(RTData[[#This Row],[Ticker_Symbol]],TickerList!$G24:$G118,TickerList!O24:O118) -> 0.0418 | AB25: 0.0001 | AC25: 0.003 | AD25: 21.47/20.14 | AE25: =_xlfn.LET(_xlpm.New1YT,RTData[[#This Row],[1YT]], _xlpm.Old1YT,IF(ISNUMBER(RTData[[#This Row],[Old1YT]]),RTData[[#This Row],[Old1YT]],VALUE(LEFT(RTData[[#This Row],[Old1YT]],FIND("/",RTData[[#This Row],[Old1YT]],1)-1))), IF(OR(RTData[[#This Row],[1YT]]=0,_xlpm.Old1YT=0),0,(_xlpm.New1YT-_xlpm.Old1YT)/_xlpm.Old1YT)) -> 0.31730321 | AF25: =TEXT(RTData[[#This Row],[1YT]],"#,#0.00")&" < "&RTData[[#This Row],[Old1YT]] -> 28.28 < 21.47/20.14
A26: {=_xlfn.SINGLE(RTData[suffix])&_FV(RTData[[#This Row],[Company Name]],"Ticker symbol",TRUE)} -> IAG | B26: =D99 -> 0.87001914 | C26: #VALUE! | D26: {=_FV(RTData[[#This Row],[Company Name]],"Currency")} -> GBp | E26: {=_FV(RTData[[#This Row],[Company Name]],"Last trade time",TRUE)} -> 45966.714 | F26: {=_FV(RTData[[#This Row],[Company Name]],"Previous close",TRUE)} -> 422.6 | G26: {=_FV(RTData[[#This Row],[Company Name]],"Open")} -> 421.1 | H26: {=_FV(RTData[[#This Row],[Company Name]],"Price")} -> 425.2 | I26: {=_FV(RTData[[#This Row],[Company Name]],"Low")} -> 419.5 | J26: {=_FV(RTData[[#This Row],[Company Name]],"High")} -> 426.1 | K26: {=IFERROR(_FV(RTData[[#This Row],[Company Name]],"P/E",TRUE),99)} -> 7.6527 | L26: {=_FV(RTData[[#This Row],[Company Name]],"Change")} -> 2.6 | M26: {=_FV(RTData[[#This Row],[Company Name]],"Change (%)",TRUE)} -> 0.006152 | N26: {=_FV(RTData[[#This Row],[Company Name]],"52 week low",TRUE)} -> 207.6 | O26: {=_FV(RTData[[#This Row],[Company Name]],"52 week high",TRUE)} -> 429.3 | P26: {=_FV(RTData[[#This Row],[Company Name]],"Volume")} -> 10087501 | Q26: {=_FV(RTData[[#This Row],[Company Name]],"Volume average",TRUE)} -> 11911510 | R26: {=_FV(RTData[[#This Row],[Company Name]],"Beta")} -> 2.2967 | T26: V | U26: {=_FV(RTData[[#This Row],[Company Name]],"Exchange abbreviation",TRUE)} -> XLON | V26: =IFERROR(RTData[[#This Row],[Volume]]/RTData[[#This Row],[Volume average]],1) -> 0.84687004 | X26: =_xlfn.XLOOKUP(RTData[[#This Row],[Ticker_Symbol]],TickerList!$G25:$G119,TickerList!L25:L119) -> 464.0942 | Y26: =_xlfn.XLOOKUP(RTData[[#This Row],[Ticker_Symbol]],TickerList!$G25:$G119,TickerList!M25:M119) -> 45834 | Z26: =_xlfn.XLOOKUP(RTData[[#This Row],[Ticker_Symbol]],TickerList!$G25:$G119,TickerList!N25:N119) -> 0 | AA26: =_xlfn.XLOOKUP(RTData[[#This Row],[Ticker_Symbol]],TickerList!$G25:$G119,TickerList!O25:O119) -> 0.0183 | AB26: 0.0001 | AC26: 0.003 | AD26: 36.26 | AE26: =_xlfn.LET(_xlpm.New1YT,RTData[[#This Row],[1YT]], _xlpm.Old1YT,IF(ISNUMBER(RTData[[#This Row],[Old1YT]]),RTData[[#This Row],[Old1YT]],VALUE(LEFT(RTData[[#This Row],[Old1YT]],FIND("/",RTData[[#This Row],[Old1YT]],1)-1))), IF(OR(RTData[[#This Row],[1YT]]=0,_xlpm.Old1YT=0),0,(_xlpm.New1YT-_xlpm.Old1YT)/_xlpm.Old1YT)) -> 11.799068 | AF26: =TEXT(RTData[[#This Row],[1YT]],"#,#0.00")&" < "&RTData[[#This Row],[Old1YT]] -> 464.09 < 36.26
A27: {=_xlfn.SINGLE(RTData[suffix])&_FV(RTData[[#This Row],[Company Name]],"Ticker symbol",TRUE)} -> KR | B27: =D101/100 -> 0.011358473 | C27: #VALUE! | D27: {=_FV(RTData[[#This Row],[Company Name]],"Currency")} -> USD | E27: {=_FV(RTData[[#This Row],[Company Name]],"Last trade time",TRUE)} -> 45967 | F27: {=_FV(RTData[[#This Row],[Company Name]],"Previous close",TRUE)} -> 63.76 | G27: {=_FV(RTData[[#This Row],[Company Name]],"Open")} -> 63.77 | H27: {=_FV(RTData[[#This Row],[Company Name]],"Price")} -> 63.15 | I27: {=_FV(RTData[[#This Row],[Company Name]],"Low")} -> 62.97 | J27: {=_FV(RTData[[#This Row],[Company Name]],"High")} -> 64.0857 | K27: {=IFERROR(_FV(RTData[[#This Row],[Company Name]],"P/E",TRUE),99)} -> 15.9987 | L27: {=_FV(RTData[[#This Row],[Company Name]],"Change")} -> -0.61 | M27: {=_FV(RTData[[#This Row],[Company Name]],"Change (%)",TRUE)} -> -0.009567 | N27: {=_FV(RTData[[#This Row],[Company Name]],"52 week low",TRUE)} -> 56.25 | O27: {=_FV(RTData[[#This Row],[Company Name]],"52 week high",TRUE)} -> 74.9 | P27: {=_FV(RTData[[#This Row],[Company Name]],"Volume")} -> 6734624 | Q27: {=_FV(RTData[[#This Row],[Company Name]],"Volume average",TRUE)} -> 6243449 | R27: {=_FV(RTData[[#This Row],[Company Name]],"Beta")} -> 0.5812 | T27: V | U27: {=_FV(RTData[[#This Row],[Company Name]],"Exchange abbreviation",TRUE)} -> XNYS | V27: =IFERROR(RTData[[#This Row],[Volume]]/RTData[[#This Row],[Volume average]],1) -> 1.0786705 | X27: =_xlfn.XLOOKUP(RTData[[#This Row],[Ticker_Symbol]],TickerList!$G26:$G120,TickerList!L26:L120) -> 76.04545 | Y27: =_xlfn.XLOOKUP(RTData[[#This Row],[Ticker_Symbol]],TickerList!$G26:$G120,TickerList!M26:M120) -> 45975 | Z27: =_xlfn.XLOOKUP(RTData[[#This Row],[Ticker_Symbol]],TickerList!$G26:$G120,TickerList!N26:N120) -> Dec 4, 2025 | AA27: =_xlfn.XLOOKUP(RTData[[#This Row],[Ticker_Symbol]],TickerList!$G26:$G120,TickerList!O26:O120) -> 0.022 | AC27: 0.003 | AD27: 393.1 | AE27: =_xlfn.LET(_xlpm.New1YT,RTData[[#This Row],[1YT]], _xlpm.Old1YT,IF(ISNUMBER(RTData[[#This Row],[Old1YT]]),RTData[[#This Row],[Old1YT]],VALUE(LEFT(RTData[[#This Row],[Old1YT]],FIND("/",RTData[[#This Row],[Old1YT]],1)-1))), IF(OR(RTData[[#This Row],[1YT]]=0,_xlpm.Old1YT=0),0,(_xlpm.New1YT-_xlpm.Old1YT)/_xlpm.Old1YT)) -> -0.80654935 | AF27: =TEXT(RTData[[#This Row],[1YT]],"#,#0.00")&" < "&RTData[[#This Row],[Old1YT]] -> 76.05 < 393.1
